Workbook

Sheet README
A1: CPI Component Workbook
A3: Build timestamp | B3: 2026-10-24 18:32 UTC
A4: Data as of | B4: Sep 2026
A5: Latest 3 reference months | B5: Jul 2026, Aug 2026, Sep 2026
A6: Next CPI release | B6: 2027-05-12 08:30AM
A7: BLS_API_KEY detected | B7: yes
A8: Refresh command | B8: BLS_API_KEY=... python build_workbook.py
A9: Source of truth | B9: BLS Public Data API, LABSTAT cu.item/cu.series, and BLS relative-importance tables
A12: Notes
A13: Derived m/m, y/y, price-updated relative importance, and contribution cells are Excel formulas that reference Data_NSA and Data_SA.
A15: Primary BLS URLs
A16: bls_api | B16: https://api.bls.gov/publicAPI/v2/timeseries/data/
A17: api_registration | B17: https://data.bls.gov/registrationEngine/
A18: labstat_base | B18: https://download.bls.gov/pub/time.series/cu/
A19: cu_item | B19: https://download.bls.gov/pub/time.series/cu/cu.item
A20: cu_series | B20: https://download.bls.gov/pub/time.series/cu/cu.series
A21: cu_current | B21: https://download.bls.gov/pub/time.series/cu/cu.data.0.Current
A22: relative_importance | B22: https://www.bls.gov/cpi/tables/relative-importance/
A23: relative_importance_xlsx | B23: https://www.bls.gov/web/cpi/cpi-relative-importance.xlsx
A24: news_release | B24: https://www.bls.gov/news.release/cpi.nr0.htm
A25: news_table_1 | B25: https://www.bls.gov/news.release/cpi.t01.htm
A26: news_table_2 | B26: https://www.bls.gov/news.release/cpi.t02.htm
A27: supplemental | B27: https://www.bls.gov/web/cpi.supp.toc.htm
... A36: cost_weights | B36: https://www.bls.gov/cpi/tables/consumer-expenditure/cost-weights.htm

Sheet Dashboard
A1: CPI Dashboard
A3: Data as of | B3: Sep 2026
A5: Headline and core | F5: Summary groups
A6: Metric | B6: Jul 2026 | C6: Aug 2026 | D6: Sep 2026 | F6: Group | G6: Latest SA m/m | H6: Contribution pp
A7: All items SA m/m | B7: =IFERROR(INDEX(Latest_3M!$K:$K,MATCH("SA0",Latest_3M!$A:$A,0)),"") | C7: =IFERROR(INDEX(Latest_3M!$Q:$Q,MATCH("SA0",Latest_3M!$A:$A,0)),"") | D7: =IFERROR(INDEX(Latest_3M!$W:$W,MATCH("SA0",Latest_3M!$A:$A,0)),"") | F7: Food | G7: =IFERROR(INDEX(Latest_3M!$W:$W,MATCH("SAF1",Latest_3M!$A:$A,0)),"") | H7: =IFERROR(INDEX(Latest_3M!$Z:$Z,MATCH("SAF1",Latest_3M!$A:$A,0)),"")
A8: All items NSA y/y | B8: =IFERROR(INDEX(Latest_3M!$L:$L,MATCH("SA0",Latest_3M!$A:$A,0)),"") | C8: =IFERROR(INDEX(Latest_3M!$R:$R,MATCH("SA0",Latest_3M!$A:$A,0)),"") | D8: =IFERROR(INDEX(Latest_3M!$X:$X,MATCH("SA0",Latest_3M!$A:$A,0)),"") | F8: Energy | G8: =IFERROR(INDEX(Latest_3M!$W:$W,MATCH("SA0E",Latest_3M!$A:$A,0)),"") | H8: =IFERROR(INDEX(Latest_3M!$Z:$Z,MATCH("SA0E",Latest_3M!$A:$A,0)),"")
A9: Core SA m/m | B9: =IFERROR(INDEX(Latest_3M!$K:$K,MATCH("SA0L1E",Latest_3M!$A:$A,0)),"") | C9: =IFERROR(INDEX(Latest_3M!$Q:$Q,MATCH("SA0L1E",Latest_3M!$A:$A,0)),"") | D9: =IFERROR(INDEX(Latest_3M!$W:$W,MATCH("SA0L1E",Latest_3M!$A:$A,0)),"") | F9: Shelter | G9: =IFERROR(INDEX(Latest_3M!$W:$W,MATCH("SAH1",Latest_3M!$A:$A,0)),"") | H9: =IFERROR(INDEX(Latest_3M!$Z:$Z,MATCH("SAH1",Latest_3M!$A:$A,0)),"")
A10: Core NSA y/y | B10: =IFERROR(INDEX(Latest_3M!$L:$L,MATCH("SA0L1E",Latest_3M!$A:$A,0)),"") | C10: =IFERROR(INDEX(Latest_3M!$R:$R,MATCH("SA0L1E",Latest_3M!$A:$A,0)),"") | D10: =IFERROR(INDEX(Latest_3M!$X:$X,MATCH("SA0L1E",Latest_3M!$A:$A,0)),"") | F10: Core | G10: =IFERROR(INDEX(Latest_3M!$W:$W,MATCH("SA0L1E",Latest_3M!$A:$A,0)),"") | H10: =IFERROR(INDEX(Latest_3M!$Z:$Z,MATCH("SA0L1E",Latest_3M!$A:$A,0)),"")
A13: Top contributors, Sep 2026
A14: Rank | B14: item_code | C14: component | D14: SA contribution pp
A15: 1 | B15: SA0 | C15: All items | D15: =IFERROR(INDEX(Latest_3M!$Z:$Z,MATCH(B15,Latest_3M!$A:$A,0)),"")
A16: 2 | B16: SA0L1 | C16: All items less food | D16: =IFERROR(INDEX(Latest_3M!$Z:$Z,MATCH(B16,Latest_3M!$A:$A,0)),"")
A17: 3 | B17: SA0L5 | C17: All items less medical care | D17: =IFERROR(INDEX(Latest_3M!$Z:$Z,MATCH(B17,Latest_3M!$A:$A,0)),"")
A18: 4 | B18: SA0L2 | C18: All items less shelter | D18: =IFERROR(INDEX(Latest_3M!$Z:$Z,MATCH(B18,Latest_3M!$A:$A,0)),"")
A19: 5 | B19: SAC | C19: Commodities | D19: =IFERROR(INDEX(Latest_3M!$Z:$Z,MATCH(B19,Latest_3M!$A:$A,0)),"")
A20: 6 | B20: SACL11 | C20: Commodities less food and beverages | D20: =IFERROR(INDEX(Latest_3M!$Z:$Z,MATCH(B20,Latest_3M!$A:$A,0)),"")
A21: 7 | B21: SACL1 | C21: Commodities less food | D21: =IFERROR(INDEX(Latest_3M!$Z:$Z,MATCH(B21,Latest_3M!$A:$A,0)),"")
A22: 8 | B22: SACE | C22: Energy commodities | D22: =IFERROR(INDEX(Latest_3M!$Z:$Z,MATCH(B22,Latest_3M!$A:$A,0)),"")
A23: 9 | B23: SA0E | C23: Energy | D23: =IFERROR(INDEX(Latest_3M!$Z:$Z,MATCH(B23,Latest_3M!$A:$A,0)),"")
A24: 10 | B24: SANL13 | C24: Nondurables less food and apparel | D24: =IFERROR(INDEX(Latest_3M!$Z:$Z,MATCH(B24,Latest_3M!$A:$A,0)),"")

Sheet Component_Tree
A1: item_code | B1: name | C1: parent | D1: display_level | E1: is_item_stratum | F1: sort_sequence
A2: SA0 | B2: All items | D2: 0 | E2: TRUE | F2: 1
A3: AA0 | B3: All items - old base | C3: SA0 | D3: 0 | E3: TRUE | F3: 2
A4: SAF | B4: Food and beverages | C4: SA0 | D4: 0 | E4: FALSE | F4: 3
A5: SAF1 | B5: Food | C5: SAF | D5: 1 | E5: FALSE | F5: 4
A6: SAF11 | B6: Food at home | C6: SAF1 | D6: 2 | E6: FALSE | F6: 5
A7: SAF111 | B7: Cereals and bakery products | C7: SAF11 | D7: 3 | E7: FALSE | F7: 6
A8: SEFA | B8: Cereals and cereal products | C8: SAF111 | D8: 4 | E8: FALSE | F8: 7
A9: SEFA01 | B9: Flour and prepared flour mixes | C9: SEFA | D9: 5 | E9: TRUE | F9: 8
A10: SEFA02 | B10: Breakfast cereal | C10: SEFA | D10: 5 | E10: TRUE | F10: 9
A11: SEFA03 | B11: Rice, pasta, cornmeal | C11: SEFA | D11: 5 | E11: FALSE | F11: 10
A12: SS01031 | B12: Rice | C12: SEFA03 | D12: 6 | E12: TRUE | F12: 11
A13: SEFB | B13: Bakery products | C13: SAF111 | D13: 4 | E13: FALSE | F13: 12
A14: SEFB01 | B14: Bread | C14: SEFB | D14: 5 | E14: FALSE | F14: 13
... A399: SERAS | B399: Video and audio services | C399: SAG | D399: 1 | E399: TRUE | F399: 398
A400: SA0R | B400: Purchasing power of the consumer dollar | D400: 0 | E400: TRUE | F400: 399
A401: AA0R | B401: Purchasing power of the consumer dollar - old base | D401: 0 | E401: TRUE | F401: 400

Sheet Methodology
A1: item_code | B1: component | C1: formula | D1: collection | E1: qa_method | F1: alt_data | G1: factsheet_or_index | H1: handbook_calculation | I1: nsa_series | J1: sa_series
A2: SA0 | B2: All items | C2: aggregate | D2: aggregate | E2: aggregate | G2: factsheet/index | H2: calculation handbook | I2: CUUR0000SA0 | J2: CUSR0000SA0
A3: AA0 | B3: All items - old base | C3: GM | D3: monthly in New York/Los Angeles/Chicago; often bimonthly elsewhere | E3: cell-relative imputation for missing quotes; direct comparison/direct QA as applicable | G3: factsheet/index | H3: calculation handbook | I3: CUUR0000AA0
A4: SAF | B4: Food and beverages | C4: aggregate | D4: aggregate | E4: aggregate of component methods | G4: factsheet/index | H4: calculation handbook | I4: CUUR0000SAF | J4: CUSR0000SAF
A5: SAF1 | B5: Food | C5: aggregate | D5: aggregate | E5: aggregate | G5: factsheet/index | H5: calculation handbook | I5: CUUR0000SAF1 | J5: CUSR0000SAF1
A6: SAF11 | B6: Food at home | C6: GM | D6: direct collection; monthly in all areas | E6: cell-relative imputation common; seasonal-item pricing rules | G6: factsheet/index | H6: calculation handbook | I6: CUUR0000SAF11 | J6: CUSR0000SAF11
A7: SAF111 | B7: Cereals and bakery products | C7: GM | D7: monthly | E7: cell-relative | G7: factsheet/index | H7: calculation handbook | I7: CUUR0000SAF111 | J7: CUSR0000SAF111
A8: SEFA | B8: Cereals and cereal products | C8: aggregate | D8: aggregate | E8: aggregate of component methods | G8: factsheet/index | H8: calculation handbook | I8: CUUR0000SEFA | J8: CUSR0000SEFA
A9: SEFA01 | B9: Flour and prepared flour mixes | C9: GM | D9: monthly food collection where sampled | E9: cell-relative imputation for missing quotes; direct comparison/direct QA as applicable | G9: factsheet/index | H9: calculation handbook | I9: CUUR0000SEFA01 | J9: CUSR0000SEFA01
A10: SEFA02 | B10: Breakfast cereal | C10: GM | D10: monthly food collection where sampled | E10: cell-relative imputation for missing quotes; direct comparison/direct QA as applicable | G10: factsheet/index | H10: calculation handbook | I10: CUUR0000SEFA02 | J10: CUSR0000SEFA02
A11: SEFA03 | B11: Rice, pasta, cornmeal | C11: aggregate | D11: aggregate | E11: aggregate of component methods | G11: factsheet/index | H11: calculation handbook | I11: CUUR0000SEFA03 | J11: CUSR0000SEFA03
A12: SS01031 | B12: Rice | C12: GM | D12: monthly in New York/Los Angeles/Chicago; often bimonthly elsewhere | E12: cell-relative imputation for missing quotes; direct comparison/direct QA as applicable | G12: factsheet/index | H12: calculation handbook | I12: CUUR0000SS01031
A13: SEFB | B13: Bakery products | C13: aggregate | D13: aggregate | E13: aggregate of component methods | G13: factsheet/index | H13: calculation handbook | I13: CUUR0000SEFB | J13: CUSR0000SEFB
A14: SEFB01 | B14: Bread | C14: aggregate | D14: aggregate | E14: aggregate of component methods | G14: factsheet/index | H14: calculation handbook | I14: CUUR0000SEFB01 | J14: CUSR0000SEFB01
A15: SS02011 | B15: White bread | C15: GM | D15: monthly in New York/Los Angeles/Chicago; often bimonthly elsewhere | E15: cell-relative imputation for missing quotes; direct comparison/direct QA as applicable | G15: factsheet/index | H15: calculation handbook | I15: CUUR0000SS02011
A16: SS02021 | B16: Bread other than white | C16: GM | D16: monthly in New York/Los Angeles/Chicago; often bimonthly elsewhere | E16: cell-relative imputation for missing quotes; direct comparison/direct QA as applicable | G16: factsheet/index | H16: calculation handbook | I16: CUUR0000SS02021
A17: SEFB02 | B17: Fresh biscuits, rolls, muffins | C17: GM | D17: monthly food collection where sampled | E17: cell-relative imputation for missing quotes; direct comparison/direct QA as applicable | G17: factsheet/index | H17: calculation handbook | I17: CUUR0000SEFB02 | J17: CUSR0000SEFB02
A18: SEFB03 | B18: Cakes, cupcakes, and cookies | C18: aggregate | D18: aggregate | E18: aggregate of component methods | G18: factsheet/index | H18: calculation handbook | I18: CUUR0000SEFB03 | J18: CUSR0000SEFB03
A19: SS02041 | B19: Fresh cakes and cupcakes | C19: GM | D19: monthly in New York/Los Angeles/Chicago; often bimonthly elsewhere | E19: cell-relative imputation for missing quotes; direct comparison/direct QA as applicable | G19: factsheet/index | H19: calculation handbook | I19: CUUR0000SS02041
A20: SS02042 | B20: Cookies | C20: GM | D20: monthly in New York/Los Angeles/Chicago; often bimonthly elsewhere | E20: cell-relative imputation for missing quotes; direct comparison/direct QA as applicable | G20: factsheet/index | H20: calculation handbook | I20: CUUR0000SS02042 | J20: CUSR0000SS02042
A21: SEFB04 | B21: Other bakery products | C21: aggregate | D21: aggregate | E21: aggregate of component methods | G21: factsheet/index | H21: calculation handbook | I21: CUUR0000SEFB04 | J21: CUSR0000SEFB04
A22: SS02063 | B22: Fresh sweetrolls, coffeecakes, doughnuts | C22: GM | D22: monthly in New York/Los Angeles/Chicago; often bimonthly elsewhere | E22: cell-relative imputation for missing quotes; direct comparison/direct QA as applicable | G22: factsheet/index | H22: calculation handbook | I22: CUUR0000SS02063
A23: SS0206A | B23: Crackers, bread, and cracker products | C23: GM | D23: monthly in New York/Los Angeles/Chicago; often bimonthly elsewhere | E23: cell-relative imputation for missing quotes; direct comparison/direct QA as applicable | G23: factsheet/index | H23: calculation handbook | I23: CUUR0000SS0206A | J23: CUSR0000SS0206A
A24: SS0206B | B24: Frozen and refrigerated bakery products, pies, tarts, turnovers | C24: GM | D24: monthly in New York/Los Angeles/Chicago; often bimonthly elsewhere | E24: cell-relative imputation for missing quotes; direct comparison/direct QA as applicable | G24: factsheet/index | H24: calculation handbook | I24: CUUR0000SS0206B | J24: CUSR0000SS0206B
A25: SAF112 | B25: Meats, poultry, fish, and eggs | C25: GM | D25: monthly | E25: cell-relative | G25: factsheet/index | H25: calculation handbook | I25: CUUR0000SAF112 | J25: CUSR0000SAF112
A26: SAF1121 | B26: Meats, poultry, and fish | C26: aggregate | D26: aggregate | E26: aggregate of component methods | G26: factsheet/index | H26: calculation handbook | I26: CUUR0000SAF1121 | J26: CUSR0000SAF1121
A27: SAF11211 | B27: Meats | C27: aggregate | D27: aggregate | E27: aggregate of component methods | G27: factsheet/index | H27: calculation handbook | I27: CUUR0000SAF11211 | J27: CUSR0000SAF11211
A28: SEFC | B28: Beef and veal | C28: aggregate | D28: aggregate | E28: aggregate of component methods | G28: factsheet/index | H28: calculation handbook | I28: CUUR0000SEFC | J28: CUSR0000SEFC
A29: SEFC01 | B29: Uncooked ground beef | C29: GM | D29: monthly food collection where sampled | E29: cell-relative imputation for missing quotes; direct comparison/direct QA as applicable | G29: factsheet/index | H29: calculation handbook | I29: CUUR0000SEFC01 | J29: CUSR0000SEFC01
A30: SEFC02 | B30: Uncooked beef roasts | C30: GM | D30: monthly food collection where sampled | E30: cell-relative imputation for missing quotes; direct comparison/direct QA as applicable | G30: factsheet/index | H30: calculation handbook | I30: CUUR0000SEFC02 | J30: CUSR0000SEFC02
A31: SEFC03 | B31: Uncooked beef steaks | C31: GM | D31: monthly food collection where sampled | E31: cell-relative imputation for missing quotes; direct comparison/direct QA as applicable | G31: factsheet/index | H31: calculation handbook | I31: CUUR0000SEFC03 | J31: CUSR0000SEFC03
A32: SEFC04 | B32: Uncooked other beef and veal | C32: GM | D32: monthly food collection where sampled | E32: cell-relative imputation for missing quotes; direct comparison/direct QA as applicable | G32: factsheet/index | H32: calculation handbook | I32: CUUR0000SEFC04
A33: SEFD | B33: Pork | C33: aggregate | D33: aggregate | E33: aggregate of component methods | G33: factsheet/index | H33: calculation handbook | I33: CUUR0000SEFD | J33: CUSR0000SEFD
A34: SEFD01 | B34: Bacon, breakfast sausage, and related products | C34: aggregate | D34: aggregate | E34: aggregate of component methods | G34: factsheet/index | H34: calculation handbook | I34: CUUR0000SEFD01 | J34: CUSR0000SEFD01
A35: SS04011 | B35: Bacon and related products | C35: GM | D35: monthly in New York/Los Angeles/Chicago; often bimonthly elsewhere | E35: cell-relative imputation for missing quotes; direct comparison/direct QA as applicable | G35: factsheet/index | H35: calculation handbook | I35: CUUR0000SS04011 | J35: CUSR0000SS04011
A36: SS04012 | B36: Breakfast sausage and related products | C36: GM | D36: monthly in New York/Los Angeles/Chicago; often bimonthly elsewhere | E36: cell-relative imputation for missing quotes; direct comparison/direct QA as applicable | G36: factsheet/index | H36: calculation handbook | I36: CUUR0000SS04012 | J36: CUSR0000SS04012
A37: SEFD02 | B37: Ham | C37: aggregate | D37: aggregate | E37: aggregate of component methods | G37: factsheet/index | H37: calculation handbook | I37: CUUR0000SEFD02 | J37: CUSR0000SEFD02
A38: SS04031 | B38: Ham, excluding canned | C38: GM | D38: monthly in New York/Los Angeles/Chicago; often bimonthly elsewhere | E38: cell-relative imputation for missing quotes; direct comparison/direct QA as applicable | G38: factsheet/index | H38: calculation handbook | I38: CUUR0000SS04031 | J38: CUSR0000SS04031
A39: SEFD03 | B39: Pork chops | C39: GM | D39: monthly food collection where sampled | E39: cell-relative imputation for missing quotes; direct comparison/direct QA as applicable | G39: factsheet/index | H39: calculation handbook | I39: CUUR0000SEFD03 | J39: CUSR0000SEFD03
A40: SEFD04 | B40: Other pork including roasts, steaks, and ribs | C40: GM | D40: monthly food collection where sampled | E40: cell-relative imputation for missing quotes; direct comparison/direct QA as applicable | G40: factsheet/index | H40: calculation handbook | I40: CUUR0000SEFD04 | J40: CUSR0000SEFD04
...

Sheet Weights
A1: item_code | B1: component | C1: series_nsa | D1: December RI % | E1: December RI month | F1: CE weight vintage | G1: 46204 | H1: 46235 | I1: 46266
A2: SA0 | B2: All items | C2: CUUR0000SA0 | D2: 100 | E2: 45992 | F2: 2024 | G2: =IFERROR(100*($D2*(INDEX('Data_NSA'!$A:$OK,MATCH(G$1,'Data_NSA'!$A:$A,0),MATCH($C2,'Data_NSA'!$1:$1,0))/INDEX('Data_NSA'!$A:$OK,MATCH($E2,'Data_NSA'!$A:$A,0),MATCH($C2,'Data_NSA'!$1:$1,0))))/(100*(INDEX('Data_NSA'!$A:$OK,MATCH(G$1,'Data_NSA'!$A:$A,0),MATCH("CUUR0000SA0",'Data_NSA'!$1:$1,0))/INDEX('Data_NSA'!$A:$OK,MATCH($E2,'Data_NSA'!$A:$A,0),MATCH("CUUR0000SA0",'Data_NSA'!$1:$1,0)))),"") | H2: =IFERROR(100*($D2*(INDEX('Data_NSA'!$A:$OK,MATCH(H$1,'Data_NSA'!$A:$A,0),MATCH($C2,'Data_NSA'!$1:$1,0))/INDEX('Data_NSA'!$A:$OK,MATCH($E2,'Data_NSA'!$A:$A,0),MATCH($C2,'Data_NSA'!$1:$1,0))))/(100*(INDEX('Data_NSA'!$A:$OK,MATCH(H$1,'Data_NSA'!$A:$A,0),MATCH("CUUR0000SA0",'Data_NSA'!$1:$1,0))/INDEX('Data_NSA'!$A:$OK,MATCH($E2,'Data_NSA'!$A:$A,0),MATCH("CUUR0000SA0",'Data_NSA'!$1:$1,0)))),"") | I2: =IFERROR(100*($D2*(INDEX('Data_NSA'!$A:$OK,MATCH(I$1,'Data_NSA'!$A:$A,0),MATCH($C2,'Data_NSA'!$1:$1,0))/INDEX('Data_NSA'!$A:$OK,MATCH($E2,'Data_NSA'!$A:$A,0),MATCH($C2,'Data_NSA'!$1:$1,0))))/(100*(INDEX('Data_NSA'!$A:$OK,MATCH(I$1,'Data_NSA'!$A:$A,0),MATCH("CUUR0000SA0",'Data_NSA'!$1:$1,0))/INDEX('Data_NSA'!$A:$OK,MATCH($E2,'Data_NSA'!$A:$A,0),MATCH("CUUR0000SA0",'Data_NSA'!$1:$1,0)))),"")
A3: AA0 | B3: All items - old base | C3: CUUR0000AA0 | E3: 45992 | F3: 2024 | G3: =IFERROR(100*($D3*(INDEX('Data_NSA'!$A:$OK,MATCH(G$1,'Data_NSA'!$A:$A,0),MATCH($C3,'Data_NSA'!$1:$1,0))/INDEX('Data_NSA'!$A:$OK,MATCH($E3,'Data_NSA'!$A:$A,0),MATCH($C3,'Data_NSA'!$1:$1,0))))/(100*(INDEX('Data_NSA'!$A:$OK,MATCH(G$1,'Data_NSA'!$A:$A,0),MATCH("CUUR0000SA0",'Data_NSA'!$1:$1,0))/INDEX('Data_NSA'!$A:$OK,MATCH($E3,'Data_NSA'!$A:$A,0),MATCH("CUUR0000SA0",'Data_NSA'!$1:$1,0)))),"") | H3: =IFERROR(100*($D3*(INDEX('Data_NSA'!$A:$OK,MATCH(H$1,'Data_NSA'!$A:$A,0),MATCH($C3,'Data_NSA'!$1:$1,0))/INDEX('Data_NSA'!$A:$OK,MATCH($E3,'Data_NSA'!$A:$A,0),MATCH($C3,'Data_NSA'!$1:$1,0))))/(100*(INDEX('Data_NSA'!$A:$OK,MATCH(H$1,'Data_NSA'!$A:$A,0),MATCH("CUUR0000SA0",'Data_NSA'!$1:$1,0))/INDEX('Data_NSA'!$A:$OK,MATCH($E3,'Data_NSA'!$A:$A,0),MATCH("CUUR0000SA0",'Data_NSA'!$1:$1,0)))),"") | I3: =IFERROR(100*($D3*(INDEX('Data_NSA'!$A:$OK,MATCH(I$1,'Data_NSA'!$A:$A,0),MATCH($C3,'Data_NSA'!$1:$1,0))/INDEX('Data_NSA'!$A:$OK,MATCH($E3,'Data_NSA'!$A:$A,0),MATCH($C3,'Data_NSA'!$1:$1,0))))/(100*(INDEX('Data_NSA'!$A:$OK,MATCH(I$1,'Data_NSA'!$A:$A,0),MATCH("CUUR0000SA0",'Data_NSA'!$1:$1,0))/INDEX('Data_NSA'!$A:$OK,MATCH($E3,'Data_NSA'!$A:$A,0),MATCH("CUUR0000SA0",'Data_NSA'!$1:$1,0)))),"")
A4: SAF | B4: Food and beverages | C4: CUUR0000SAF | D4: 14.539 | E4: 45992 | F4: 2024 | G4: =IFERROR(100*($D4*(INDEX('Data_NSA'!$A:$OK,MATCH(G$1,'Data_NSA'!$A:$A,0),MATCH($C4,'Data_NSA'!$1:$1,0))/INDEX('Data_NSA'!$A:$OK,MATCH($E4,'Data_NSA'!$A:$A,0),MATCH($C4,'Data_NSA'!$1:$1,0))))/(100*(INDEX('Data_NSA'!$A:$OK,MATCH(G$1,'Data_NSA'!$A:$A,0),MATCH("CUUR0000SA0",'Data_NSA'!$1:$1,0))/INDEX('Data_NSA'!$A:$OK,MATCH($E4,'Data_NSA'!$A:$A,0),MATCH("CUUR0000SA0",'Data_NSA'!$1:$1,0)))),"") | H4: =IFERROR(100*($D4*(INDEX('Data_NSA'!$A:$OK,MATCH(H$1,'Data_NSA'!$A:$A,0),MATCH($C4,'Data_NSA'!$1:$1,0))/INDEX('Data_NSA'!$A:$OK,MATCH($E4,'Data_NSA'!$A:$A,0),MATCH($C4,'Data_NSA'!$1:$1,0))))/(100*(INDEX('Data_NSA'!$A:$OK,MATCH(H$1,'Data_NSA'!$A:$A,0),MATCH("CUUR0000SA0",'Data_NSA'!$1:$1,0))/INDEX('Data_NSA'!$A:$OK,MATCH($E4,'Data_NSA'!$A:$A,0),MATCH("CUUR0000SA0",'Data_NSA'!$1:$1,0)))),"") | I4: =IFERROR(100*($D4*(INDEX('Data_NSA'!$A:$OK,MATCH(I$1,'Data_NSA'!$A:$A,0),MATCH($C4,'Data_NSA'!$1:$1,0))/INDEX('Data_NSA'!$A:$OK,MATCH($E4,'Data_NSA'!$A:$A,0),MATCH($C4,'Data_NSA'!$1:$1,0))))/(100*(INDEX('Data_NSA'!$A:$OK,MATCH(I$1,'Data_NSA'!$A:$A,0),MATCH("CUUR0000SA0",'Data_NSA'!$1:$1,0))/INDEX('Data_NSA'!$A:$OK,MATCH($E4,'Data_NSA'!$A:$A,0),MATCH("CUUR0000SA0",'Data_NSA'!$1:$1,0)))),"")
A5: SAF1 | B5: Food | C5: CUUR0000SAF1 | D5: 13.698 | E5: 45992 | F5: 2024 | G5: =IFERROR(100*($D5*(INDEX('Data_NSA'!$A:$OK,MATCH(G$1,'Data_NSA'!$A:$A,0),MATCH($C5,'Data_NSA'!$1:$1,0))/INDEX('Data_NSA'!$A:$OK,MATCH($E5,'Data_NSA'!$A:$A,0),MATCH($C5,'Data_NSA'!$1:$1,0))))/(100*(INDEX('Data_NSA'!$A:$OK,MATCH(G$1,'Data_NSA'!$A:$A,0),MATCH("CUUR0000SA0",'Data_NSA'!$1:$1,0))/INDEX('Data_NSA'!$A:$OK,MATCH($E5,'Data_NSA'!$A:$A,0),MATCH("CUUR0000SA0",'Data_NSA'!$1:$1,0)))),"") | H5: =IFERROR(100*($D5*(INDEX('Data_NSA'!$A:$OK,MATCH(H$1,'Data_NSA'!$A:$A,0),MATCH($C5,'Data_NSA'!$1:$1,0))/INDEX('Data_NSA'!$A:$OK,MATCH($E5,'Data_NSA'!$A:$A,0),MATCH($C5,'Data_NSA'!$1:$1,0))))/(100*(INDEX('Data_NSA'!$A:$OK,MATCH(H$1,'Data_NSA'!$A:$A,0),MATCH("CUUR0000SA0",'Data_NSA'!$1:$1,0))/INDEX('Data_NSA'!$A:$OK,MATCH($E5,'Data_NSA'!$A:$A,0),MATCH("CUUR0000SA0",'Data_NSA'!$1:$1,0)))),"") | I5: =IFERROR(100*($D5*(INDEX('Data_NSA'!$A:$OK,MATCH(I$1,'Data_NSA'!$A:$A,0),MATCH($C5,'Data_NSA'!$1:$1,0))/INDEX('Data_NSA'!$A:$OK,MATCH($E5,'Data_NSA'!$A:$A,0),MATCH($C5,'Data_NSA'!$1:$1,0))))/(100*(INDEX('Data_NSA'!$A:$OK,MATCH(I$1,'Data_NSA'!$A:$A,0),MATCH("CUUR0000SA0",'Data_NSA'!$1:$1,0))/INDEX('Data_NSA'!$A:$OK,MATCH($E5,'Data_NSA'!$A:$A,0),MATCH("CUUR0000SA0",'Data_NSA'!$1:$1,0)))),"")
A6: SAF11 | B6: Food at home | C6: CUUR0000SAF11 | D6: 8.325 | E6: 45992 | F6: 2024 | G6: =IFERROR(100*($D6*(INDEX('Data_NSA'!$A:$OK,MATCH(G$1,'Data_NSA'!$A:$A,0),MATCH($C6,'Data_NSA'!$1:$1,0))/INDEX('Data_NSA'!$A:$OK,MATCH($E6,'Data_NSA'!$A:$A,0),MATCH($C6,'Data_NSA'!$1:$1,0))))/(100*(INDEX('Data_NSA'!$A:$OK,MATCH(G$1,'Data_NSA'!$A:$A,0),MATCH("CUUR0000SA0",'Data_NSA'!$1:$1,0))/INDEX('Data_NSA'!$A:$OK,MATCH($E6,'Data_NSA'!$A:$A,0),MATCH("CUUR0000SA0",'Data_NSA'!$1:$1,0)))),"") | H6: =IFERROR(100*($D6*(INDEX('Data_NSA'!$A:$OK,MATCH(H$1,'Data_NSA'!$A:$A,0),MATCH($C6,'Data_NSA'!$1:$1,0))/INDEX('Data_NSA'!$A:$OK,MATCH($E6,'Data_NSA'!$A:$A,0),MATCH($C6,'Data_NSA'!$1:$1,0))))/(100*(INDEX('Data_NSA'!$A:$OK,MATCH(H$1,'Data_NSA'!$A:$A,0),MATCH("CUUR0000SA0",'Data_NSA'!$1:$1,0))/INDEX('Data_NSA'!$A:$OK,MATCH($E6,'Data_NSA'!$A:$A,0),MATCH("CUUR0000SA0",'Data_NSA'!$1:$1,0)))),"") | I6: =IFERROR(100*($D6*(INDEX('Data_NSA'!$A:$OK,MATCH(I$1,'Data_NSA'!$A:$A,0),MATCH($C6,'Data_NSA'!$1:$1,0))/INDEX('Data_NSA'!$A:$OK,MATCH($E6,'Data_NSA'!$A:$A,0),MATCH($C6,'Data_NSA'!$1:$1,0))))/(100*(INDEX('Data_NSA'!$A:$OK,MATCH(I$1,'Data_NSA'!$A:$A,0),MATCH("CUUR0000SA0",'Data_NSA'!$1:$1,0))/INDEX('Data_NSA'!$A:$OK,MATCH($E6,'Data_NSA'!$A:$A,0),MATCH("CUUR0000SA0",'Data_NSA'!$1:$1,0)))),"")
A7: SAF111 | B7: Cereals and bakery products | C7: CUUR0000SAF111 | D7: 1.035 | E7: 45992 | F7: 2024 | G7: =IFERROR(100*($D7*(INDEX('Data_NSA'!$A:$OK,MATCH(G$1,'Data_NSA'!$A:$A,0),MATCH($C7,'Data_NSA'!$1:$1,0))/INDEX('Data_NSA'!$A:$OK,MATCH($E7,'Data_NSA'!$A:$A,0),MATCH($C7,'Data_NSA'!$1:$1,0))))/(100*(INDEX('Data_NSA'!$A:$OK,MATCH(G$1,'Data_NSA'!$A:$A,0),MATCH("CUUR0000SA0",'Data_NSA'!$1:$1,0))/INDEX('Data_NSA'!$A:$OK,MATCH($E7,'Data_NSA'!$A:$A,0),MATCH("CUUR0000SA0",'Data_NSA'!$1:$1,0)))),"") | H7: =IFERROR(100*($D7*(INDEX('Data_NSA'!$A:$OK,MATCH(H$1,'Data_NSA'!$A:$A,0),MATCH($C7,'Data_NSA'!$1:$1,0))/INDEX('Data_NSA'!$A:$OK,MATCH($E7,'Data_NSA'!$A:$A,0),MATCH($C7,'Data_NSA'!$1:$1,0))))/(100*(INDEX('Data_NSA'!$A:$OK,MATCH(H$1,'Data_NSA'!$A:$A,0),MATCH("CUUR0000SA0",'Data_NSA'!$1:$1,0))/INDEX('Data_NSA'!$A:$OK,MATCH($E7,'Data_NSA'!$A:$A,0),MATCH("CUUR0000SA0",'Data_NSA'!$1:$1,0)))),"") | I7: =IFERROR(100*($D7*(INDEX('Data_NSA'!$A:$OK,MATCH(I$1,'Data_NSA'!$A:$A,0),MATCH($C7,'Data_NSA'!$1:$1,0))/INDEX('Data_NSA'!$A:$OK,MATCH($E7,'Data_NSA'!$A:$A,0),MATCH($C7,'Data_NSA'!$1:$1,0))))/(100*(INDEX('Data_NSA'!$A:$OK,MATCH(I$1,'Data_NSA'!$A:$A,0),MATCH("CUUR0000SA0",'Data_NSA'!$1:$1,0))/INDEX('Data_NSA'!$A:$OK,MATCH($E7,'Data_NSA'!$A:$A,0),MATCH("CUUR0000SA0",'Data_NSA'!$1:$1,0)))),"")
A8: SEFA | B8: Cereals and cereal products | C8: CUUR0000SEFA | D8: 0.315 | E8: 45992 | F8: 2024 | G8: =IFERROR(100*($D8*(INDEX('Data_NSA'!$A:$OK,MATCH(G$1,'Data_NSA'!$A:$A,0),MATCH($C8,'Data_NSA'!$1:$1,0))/INDEX('Data_NSA'!$A:$OK,MATCH($E8,'Data_NSA'!$A:$A,0),MATCH($C8,'Data_NSA'!$1:$1,0))))/(100*(INDEX('Data_NSA'!$A:$OK,MATCH(G$1,'Data_NSA'!$A:$A,0),MATCH("CUUR0000SA0",'Data_NSA'!$1:$1,0))/INDEX('Data_NSA'!$A:$OK,MATCH($E8,'Data_NSA'!$A:$A,0),MATCH("CUUR0000SA0",'Data_NSA'!$1:$1,0)))),"") | H8: =IFERROR(100*($D8*(INDEX('Data_NSA'!$A:$OK,MATCH(H$1,'Data_NSA'!$A:$A,0),MATCH($C8,'Data_NSA'!$1:$1,0))/INDEX('Data_NSA'!$A:$OK,MATCH($E8,'Data_NSA'!$A:$A,0),MATCH($C8,'Data_NSA'!$1:$1,0))))/(100*(INDEX('Data_NSA'!$A:$OK,MATCH(H$1,'Data_NSA'!$A:$A,0),MATCH("CUUR0000SA0",'Data_NSA'!$1:$1,0))/INDEX('Data_NSA'!$A:$OK,MATCH($E8,'Data_NSA'!$A:$A,0),MATCH("CUUR0000SA0",'Data_NSA'!$1:$1,0)))),"") | I8: =IFERROR(100*($D8*(INDEX('Data_NSA'!$A:$OK,MATCH(I$1,'Data_NSA'!$A:$A,0),MATCH($C8,'Data_NSA'!$1:$1,0))/INDEX('Data_NSA'!$A:$OK,MATCH($E8,'Data_NSA'!$A:$A,0),MATCH($C8,'Data_NSA'!$1:$1,0))))/(100*(INDEX('Data_NSA'!$A:$OK,MATCH(I$1,'Data_NSA'!$A:$A,0),MATCH("CUUR0000SA0",'Data_NSA'!$1:$1,0))/INDEX('Data_NSA'!$A:$OK,MATCH($E8,'Data_NSA'!$A:$A,0),MATCH("CUUR0000SA0",'Data_NSA'!$1:$1,0)))),"")
A9: SEFA01 | B9: Flour and prepared flour mixes | C9: CUUR0000SEFA01 | D9: 0.038 | E9: 45992 | F9: 2024 | G9: =IFERROR(100*($D9*(INDEX('Data_NSA'!$A:$OK,MATCH(G$1,'Data_NSA'!$A:$A,0),MATCH($C9,'Data_NSA'!$1:$1,0))/INDEX('Data_NSA'!$A:$OK,MATCH($E9,'Data_NSA'!$A:$A,0),MATCH($C9,'Data_NSA'!$1:$1,0))))/(100*(INDEX('Data_NSA'!$A:$OK,MATCH(G$1,'Data_NSA'!$A:$A,0),MATCH("CUUR0000SA0",'Data_NSA'!$1:$1,0))/INDEX('Data_NSA'!$A:$OK,MATCH($E9,'Data_NSA'!$A:$A,0),MATCH("CUUR0000SA0",'Data_NSA'!$1:$1,0)))),"") | H9: =IFERROR(100*($D9*(INDEX('Data_NSA'!$A:$OK,MATCH(H$1,'Data_NSA'!$A:$A,0),MATCH($C9,'Data_NSA'!$1:$1,0))/INDEX('Data_NSA'!$A:$OK,MATCH($E9,'Data_NSA'!$A:$A,0),MATCH($C9,'Data_NSA'!$1:$1,0))))/(100*(INDEX('Data_NSA'!$A:$OK,MATCH(H$1,'Data_NSA'!$A:$A,0),MATCH("CUUR0000SA0",'Data_NSA'!$1:$1,0))/INDEX('Data_NSA'!$A:$OK,MATCH($E9,'Data_NSA'!$A:$A,0),MATCH("CUUR0000SA0",'Data_NSA'!$1:$1,0)))),"") | I9: =IFERROR(100*($D9*(INDEX('Data_NSA'!$A:$OK,MATCH(I$1,'Data_NSA'!$A:$A,0),MATCH($C9,'Data_NSA'!$1:$1,0))/INDEX('Data_NSA'!$A:$OK,MATCH($E9,'Data_NSA'!$A:$A,0),MATCH($C9,'Data_NSA'!$1:$1,0))))/(100*(INDEX('Data_NSA'!$A:$OK,MATCH(I$1,'Data_NSA'!$A:$A,0),MATCH("CUUR0000SA0",'Data_NSA'!$1:$1,0))/INDEX('Data_NSA'!$A:$OK,MATCH($E9,'Data_NSA'!$A:$A,0),MATCH("CUUR0000SA0",'Data_NSA'!$1:$1,0)))),"")
A10: SEFA02 | B10: Breakfast cereal | C10: CUUR0000SEFA02 | D10: 0.136 | E10: 45992 | F10: 2024 | G10: =IFERROR(100*($D10*(INDEX('Data_NSA'!$A:$OK,MATCH(G$1,'Data_NSA'!$A:$A,0),MATCH($C10,'Data_NSA'!$1:$1,0))/INDEX('Data_NSA'!$A:$OK,MATCH($E10,'Data_NSA'!$A:$A,0),MATCH($C10,'Data_NSA'!$1:$1,0))))/(100*(INDEX('Data_NSA'!$A:$OK,MATCH(G$1,'Data_NSA'!$A:$A,0),MATCH("CUUR0000SA0",'Data_NSA'!$1:$1,0))/INDEX('Data_NSA'!$A:$OK,MATCH($E10,'Data_NSA'!$A:$A,0),MATCH("CUUR0000SA0",'Data_NSA'!$1:$1,0)))),"") | H10: =IFERROR(100*($D10*(INDEX('Data_NSA'!$A:$OK,MATCH(H$1,'Data_NSA'!$A:$A,0),MATCH($C10,'Data_NSA'!$1:$1,0))/INDEX('Data_NSA'!$A:$OK,MATCH($E10,'Data_NSA'!$A:$A,0),MATCH($C10,'Data_NSA'!$1:$1,0))))/(100*(INDEX('Data_NSA'!$A:$OK,MATCH(H$1,'Data_NSA'!$A:$A,0),MATCH("CUUR0000SA0",'Data_NSA'!$1:$1,0))/INDEX('Data_NSA'!$A:$OK,MATCH($E10,'Data_NSA'!$A:$A,0),MATCH("CUUR0000SA0",'Data_NSA'!$1:$1,0)))),"") | I10: =IFERROR(100*($D10*(INDEX('Data_NSA'!$A:$OK,MATCH(I$1,'Data_NSA'!$A:$A,0),MATCH($C10,'Data_NSA'!$1:$1,0))/INDEX('Data_NSA'!$A:$OK,MATCH($E10,'Data_NSA'!$A:$A,0),MATCH($C10,'Data_NSA'!$1:$1,0))))/(100*(INDEX('Data_NSA'!$A:$OK,MATCH(I$1,'Data_NSA'!$A:$A,0),MATCH("CUUR0000SA0",'Data_NSA'!$1:$1,0))/INDEX('Data_NSA'!$A:$OK,MATCH($E10,'Data_NSA'!$A:$A,0),MATCH("CUUR0000SA0",'Data_NSA'!$1:$1,0)))),"")
A11: SEFA03 | B11: Rice, pasta, cornmeal | C11: CUUR0000SEFA03 | D11: 0.141 | E11: 45992 | F11: 2024 | G11: =IFERROR(100*($D11*(INDEX('Data_NSA'!$A:$OK,MATCH(G$1,'Data_NSA'!$A:$A,0),MATCH($C11,'Data_NSA'!$1:$1,0))/INDEX('Data_NSA'!$A:$OK,MATCH($E11,'Data_NSA'!$A:$A,0),MATCH($C11,'Data_NSA'!$1:$1,0))))/(100*(INDEX('Data_NSA'!$A:$OK,MATCH(G$1,'Data_NSA'!$A:$A,0),MATCH("CUUR0000SA0",'Data_NSA'!$1:$1,0))/INDEX('Data_NSA'!$A:$OK,MATCH($E11,'Data_NSA'!$A:$A,0),MATCH("CUUR0000SA0",'Data_NSA'!$1:$1,0)))),"") | H11: =IFERROR(100*($D11*(INDEX('Data_NSA'!$A:$OK,MATCH(H$1,'Data_NSA'!$A:$A,0),MATCH($C11,'Data_NSA'!$1:$1,0))/INDEX('Data_NSA'!$A:$OK,MATCH($E11,'Data_NSA'!$A:$A,0),MATCH($C11,'Data_NSA'!$1:$1,0))))/(100*(INDEX('Data_NSA'!$A:$OK,MATCH(H$1,'Data_NSA'!$A:$A,0),MATCH("CUUR0000SA0",'Data_NSA'!$1:$1,0))/INDEX('Data_NSA'!$A:$OK,MATCH($E11,'Data_NSA'!$A:$A,0),MATCH("CUUR0000SA0",'Data_NSA'!$1:$1,0)))),"") | I11: =IFERROR(100*($D11*(INDEX('Data_NSA'!$A:$OK,MATCH(I$1,'Data_NSA'!$A:$A,0),MATCH($C11,'Data_NSA'!$1:$1,0))/INDEX('Data_NSA'!$A:$OK,MATCH($E11,'Data_NSA'!$A:$A,0),MATCH($C11,'Data_NSA'!$1:$1,0))))/(100*(INDEX('Data_NSA'!$A:$OK,MATCH(I$1,'Data_NSA'!$A:$A,0),MATCH("CUUR0000SA0",'Data_NSA'!$1:$1,0))/INDEX('Data_NSA'!$A:$OK,MATCH($E11,'Data_NSA'!$A:$A,0),MATCH("CUUR0000SA0",'Data_NSA'!$1:$1,0)))),"")
A12: SS01031 | B12: Rice | C12: CUUR0000SS01031 | E12: 45992 | F12: 2024 | G12: =IFERROR(100*($D12*(INDEX('Data_NSA'!$A:$OK,MATCH(G$1,'Data_NSA'!$A:$A,0),MATCH($C12,'Data_NSA'!$1:$1,0))/INDEX('Data_NSA'!$A:$OK,MATCH($E12,'Data_NSA'!$A:$A,0),MATCH($C12,'Data_NSA'!$1:$1,0))))/(100*(INDEX('Data_NSA'!$A:$OK,MATCH(G$1,'Data_NSA'!$A:$A,0),MATCH("CUUR0000SA0",'Data_NSA'!$1:$1,0))/INDEX('Data_NSA'!$A:$OK,MATCH($E12,'Data_NSA'!$A:$A,0),MATCH("CUUR0000SA0",'Data_NSA'!$1:$1,0)))),"") | H12: =IFERROR(100*($D12*(INDEX('Data_NSA'!$A:$OK,MATCH(H$1,'Data_NSA'!$A:$A,0),MATCH($C12,'Data_NSA'!$1:$1,0))/INDEX('Data_NSA'!$A:$OK,MATCH($E12,'Data_NSA'!$A:$A,0),MATCH($C12,'Data_NSA'!$1:$1,0))))/(100*(INDEX('Data_NSA'!$A:$OK,MATCH(H$1,'Data_NSA'!$A:$A,0),MATCH("CUUR0000SA0",'Data_NSA'!$1:$1,0))/INDEX('Data_NSA'!$A:$OK,MATCH($E12,'Data_NSA'!$A:$A,0),MATCH("CUUR0000SA0",'Data_NSA'!$1:$1,0)))),"") | I12: =IFERROR(100*($D12*(INDEX('Data_NSA'!$A:$OK,MATCH(I$1,'Data_NSA'!$A:$A,0),MATCH($C12,'Data_NSA'!$1:$1,0))/INDEX('Data_NSA'!$A:$OK,MATCH($E12,'Data_NSA'!$A:$A,0),MATCH($C12,'Data_NSA'!$1:$1,0))))/(100*(INDEX('Data_NSA'!$A:$OK,MATCH(I$1,'Data_NSA'!$A:$A,0),MATCH("CUUR0000SA0",'Data_NSA'!$1:$1,0))/INDEX('Data_NSA'!$A:$OK,MATCH($E12,'Data_NSA'!$A:$A,0),MATCH("CUUR0000SA0",'Data_NSA'!$1:$1,0)))),"")
A13: SEFB | B13: Bakery products | C13: CUUR0000SEFB | D13: 0.721 | E13: 45992 | F13: 2024 | G13: =IFERROR(100*($D13*(INDEX('Data_NSA'!$A:$OK,MATCH(G$1,'Data_NSA'!$A:$A,0),MATCH($C13,'Data_NSA'!$1:$1,0))/INDEX('Data_NSA'!$A:$OK,MATCH($E13,'Data_NSA'!$A:$A,0),MATCH($C13,'Data_NSA'!$1:$1,0))))/(100*(INDEX('Data_NSA'!$A:$OK,MATCH(G$1,'Data_NSA'!$A:$A,0),MATCH("CUUR0000SA0",'Data_NSA'!$1:$1,0))/INDEX('Data_NSA'!$A:$OK,MATCH($E13,'Data_NSA'!$A:$A,0),MATCH("CUUR0000SA0",'Data_NSA'!$1:$1,0)))),"") | H13: =IFERROR(100*($D13*(INDEX('Data_NSA'!$A:$OK,MATCH(H$1,'Data_NSA'!$A:$A,0),MATCH($C13,'Data_NSA'!$1:$1,0))/INDEX('Data_NSA'!$A:$OK,MATCH($E13,'Data_NSA'!$A:$A,0),MATCH($C13,'Data_NSA'!$1:$1,0))))/(100*(INDEX('Data_NSA'!$A:$OK,MATCH(H$1,'Data_NSA'!$A:$A,0),MATCH("CUUR0000SA0",'Data_NSA'!$1:$1,0))/INDEX('Data_NSA'!$A:$OK,MATCH($E13,'Data_NSA'!$A:$A,0),MATCH("CUUR0000SA0",'Data_NSA'!$1:$1,0)))),"") | I13: =IFERROR(100*($D13*(INDEX('Data_NSA'!$A:$OK,MATCH(I$1,'Data_NSA'!$A:$A,0),MATCH($C13,'Data_NSA'!$1:$1,0))/INDEX('Data_NSA'!$A:$OK,MATCH($E13,'Data_NSA'!$A:$A,0),MATCH($C13,'Data_NSA'!$1:$1,0))))/(100*(INDEX('Data_NSA'!$A:$OK,MATCH(I$1,'Data_NSA'!$A:$A,0),MATCH("CUUR0000SA0",'Data_NSA'!$1:$1,0))/INDEX('Data_NSA'!$A:$OK,MATCH($E13,'Data_NSA'!$A:$A,0),MATCH("CUUR0000SA0",'Data_NSA'!$1:$1,0)))),"")
A14: SEFB01 | B14: Bread | C14: CUUR0000SEFB01 | D14: 0.175 | E14: 45992 | F14: 2024 | G14: =IFERROR(100*($D14*(INDEX('Data_NSA'!$A:$OK,MATCH(G$1,'Data_NSA'!$A:$A,0),MATCH($C14,'Data_NSA'!$1:$1,0))/INDEX('Data_NSA'!$A:$OK,MATCH($E14,'Data_NSA'!$A:$A,0),MATCH($C14,'Data_NSA'!$1:$1,0))))/(100*(INDEX('Data_NSA'!$A:$OK,MATCH(G$1,'Data_NSA'!$A:$A,0),MATCH("CUUR0000SA0",'Data_NSA'!$1:$1,0))/INDEX('Data_NSA'!$A:$OK,MATCH($E14,'Data_NSA'!$A:$A,0),MATCH("CUUR0000SA0",'Data_NSA'!$1:$1,0)))),"") | H14: =IFERROR(100*($D14*(INDEX('Data_NSA'!$A:$OK,MATCH(H$1,'Data_NSA'!$A:$A,0),MATCH($C14,'Data_NSA'!$1:$1,0))/INDEX('Data_NSA'!$A:$OK,MATCH($E14,'Data_NSA'!$A:$A,0),MATCH($C14,'Data_NSA'!$1:$1,0))))/(100*(INDEX('Data_NSA'!$A:$OK,MATCH(H$1,'Data_NSA'!$A:$A,0),MATCH("CUUR0000SA0",'Data_NSA'!$1:$1,0))/INDEX('Data_NSA'!$A:$OK,MATCH($E14,'Data_NSA'!$A:$A,0),MATCH("CUUR0000SA0",'Data_NSA'!$1:$1,0)))),"") | I14: =IFERROR(100*($D14*(INDEX('Data_NSA'!$A:$OK,MATCH(I$1,'Data_NSA'!$A:$A,0),MATCH($C14,'Data_NSA'!$1:$1,0))/INDEX('Data_NSA'!$A:$OK,MATCH($E14,'Data_NSA'!$A:$A,0),MATCH($C14,'Data_NSA'!$1:$1,0))))/(100*(INDEX('Data_NSA'!$A:$OK,MATCH(I$1,'Data_NSA'!$A:$A,0),MATCH("CUUR0000SA0",'Data_NSA'!$1:$1,0))/INDEX('Data_NSA'!$A:$OK,MATCH($E14,'Data_NSA'!$A:$A,0),MATCH("CUUR0000SA0",'Data_NSA'!$1:$1,0)))),"")
A15: SS02011 | B15: White bread | C15: CUUR0000SS02011 | E15: 45992 | F15: 2024 | G15: =IFERROR(100*($D15*(INDEX('Data_NSA'!$A:$OK,MATCH(G$1,'Data_NSA'!$A:$A,0),MATCH($C15,'Data_NSA'!$1:$1,0))/INDEX('Data_NSA'!$A:$OK,MATCH($E15,'Data_NSA'!$A:$A,0),MATCH($C15,'Data_NSA'!$1:$1,0))))/(100*(INDEX('Data_NSA'!$A:$OK,MATCH(G$1,'Data_NSA'!$A:$A,0),MATCH("CUUR0000SA0",'Data_NSA'!$1:$1,0))/INDEX('Data_NSA'!$A:$OK,MATCH($E15,'Data_NSA'!$A:$A,0),MATCH("CUUR0000SA0",'Data_NSA'!$1:$1,0)))),"") | H15: =IFERROR(100*($D15*(INDEX('Data_NSA'!$A:$OK,MATCH(H$1,'Data_NSA'!$A:$A,0),MATCH($C15,'Data_NSA'!$1:$1,0))/INDEX('Data_NSA'!$A:$OK,MATCH($E15,'Data_NSA'!$A:$A,0),MATCH($C15,'Data_NSA'!$1:$1,0))))/(100*(INDEX('Data_NSA'!$A:$OK,MATCH(H$1,'Data_NSA'!$A:$A,0),MATCH("CUUR0000SA0",'Data_NSA'!$1:$1,0))/INDEX('Data_NSA'!$A:$OK,MATCH($E15,'Data_NSA'!$A:$A,0),MATCH("CUUR0000SA0",'Data_NSA'!$1:$1,0)))),"") | I15: =IFERROR(100*($D15*(INDEX('Data_NSA'!$A:$OK,MATCH(I$1,'Data_NSA'!$A:$A,0),MATCH($C15,'Data_NSA'!$1:$1,0))/INDEX('Data_NSA'!$A:$OK,MATCH($E15,'Data_NSA'!$A:$A,0),MATCH($C15,'Data_NSA'!$1:$1,0))))/(100*(INDEX('Data_NSA'!$A:$OK,MATCH(I$1,'Data_NSA'!$A:$A,0),MATCH("CUUR0000SA0",'Data_NSA'!$1:$1,0))/INDEX('Data_NSA'!$A:$OK,MATCH($E15,'Data_NSA'!$A:$A,0),MATCH("CUUR0000SA0",'Data_NSA'!$1:$1,0)))),"")
A16: SS02021 | B16: Bread other than white | C16: CUUR0000SS02021 | E16: 45992 | F16: 2024 | G16: =IFERROR(100*($D16*(INDEX('Data_NSA'!$A:$OK,MATCH(G$1,'Data_NSA'!$A:$A,0),MATCH($C16,'Data_NSA'!$1:$1,0))/INDEX('Data_NSA'!$A:$OK,MATCH($E16,'Data_NSA'!$A:$A,0),MATCH($C16,'Data_NSA'!$1:$1,0))))/(100*(INDEX('Data_NSA'!$A:$OK,MATCH(G$1,'Data_NSA'!$A:$A,0),MATCH("CUUR0000SA0",'Data_NSA'!$1:$1,0))/INDEX('Data_NSA'!$A:$OK,MATCH($E16,'Data_NSA'!$A:$A,0),MATCH("CUUR0000SA0",'Data_NSA'!$1:$1,0)))),"") | H16: =IFERROR(100*($D16*(INDEX('Data_NSA'!$A:$OK,MATCH(H$1,'Data_NSA'!$A:$A,0),MATCH($C16,'Data_NSA'!$1:$1,0))/INDEX('Data_NSA'!$A:$OK,MATCH($E16,'Data_NSA'!$A:$A,0),MATCH($C16,'Data_NSA'!$1:$1,0))))/(100*(INDEX('Data_NSA'!$A:$OK,MATCH(H$1,'Data_NSA'!$A:$A,0),MATCH("CUUR0000SA0",'Data_NSA'!$1:$1,0))/INDEX('Data_NSA'!$A:$OK,MATCH($E16,'Data_NSA'!$A:$A,0),MATCH("CUUR0000SA0",'Data_NSA'!$1:$1,0)))),"") | I16: =IFERROR(100*($D16*(INDEX('Data_NSA'!$A:$OK,MATCH(I$1,'Data_NSA'!$A:$A,0),MATCH($C16,'Data_NSA'!$1:$1,0))/INDEX('Data_NSA'!$A:$OK,MATCH($E16,'Data_NSA'!$A:$A,0),MATCH($C16,'Data_NSA'!$1:$1,0))))/(100*(INDEX('Data_NSA'!$A:$OK,MATCH(I$1,'Data_NSA'!$A:$A,0),MATCH("CUUR0000SA0",'Data_NSA'!$1:$1,0))/INDEX('Data_NSA'!$A:$OK,MATCH($E16,'Data_NSA'!$A:$A,0),MATCH("CUUR0000SA0",'Data_NSA'!$1:$1,0)))),"")
A17: SEFB02 | B17: Fresh biscuits, rolls, muffins | C17: CUUR0000SEFB02 | D17: 0.12 | E17: 45992 | F17: 2024 | G17: =IFERROR(100*($D17*(INDEX('Data_NSA'!$A:$OK,MATCH(G$1,'Data_NSA'!$A:$A,0),MATCH($C17,'Data_NSA'!$1:$1,0))/INDEX('Data_NSA'!$A:$OK,MATCH($E17,'Data_NSA'!$A:$A,0),MATCH($C17,'Data_NSA'!$1:$1,0))))/(100*(INDEX('Data_NSA'!$A:$OK,MATCH(G$1,'Data_NSA'!$A:$A,0),MATCH("CUUR0000SA0",'Data_NSA'!$1:$1,0))/INDEX('Data_NSA'!$A:$OK,MATCH($E17,'Data_NSA'!$A:$A,0),MATCH("CUUR0000SA0",'Data_NSA'!$1:$1,0)))),"") | H17: =IFERROR(100*($D17*(INDEX('Data_NSA'!$A:$OK,MATCH(H$1,'Data_NSA'!$A:$A,0),MATCH($C17,'Data_NSA'!$1:$1,0))/INDEX('Data_NSA'!$A:$OK,MATCH($E17,'Data_NSA'!$A:$A,0),MATCH($C17,'Data_NSA'!$1:$1,0))))/(100*(INDEX('Data_NSA'!$A:$OK,MATCH(H$1,'Data_NSA'!$A:$A,0),MATCH("CUUR0000SA0",'Data_NSA'!$1:$1,0))/INDEX('Data_NSA'!$A:$OK,MATCH($E17,'Data_NSA'!$A:$A,0),MATCH("CUUR0000SA0",'Data_NSA'!$1:$1,0)))),"") | I17: =IFERROR(100*($D17*(INDEX('Data_NSA'!$A:$OK,MATCH(I$1,'Data_NSA'!$A:$A,0),MATCH($C17,'Data_NSA'!$1:$1,0))/INDEX('Data_NSA'!$A:$OK,MATCH($E17,'Data_NSA'!$A:$A,0),MATCH($C17,'Data_NSA'!$1:$1,0))))/(100*(INDEX('Data_NSA'!$A:$OK,MATCH(I$1,'Data_NSA'!$A:$A,0),MATCH("CUUR0000SA0",'Data_NSA'!$1:$1,0))/INDEX('Data_NSA'!$A:$OK,MATCH($E17,'Data_NSA'!$A:$A,0),MATCH("CUUR0000SA0",'Data_NSA'!$1:$1,0)))),"")
A18: SEFB03 | B18: Cakes, cupcakes, and cookies | C18: CUUR0000SEFB03 | D18: 0.21 | E18: 45992 | F18: 2024 | G18: =IFERROR(100*($D18*(INDEX('Data_NSA'!$A:$OK,MATCH(G$1,'Data_NSA'!$A:$A,0),MATCH($C18,'Data_NSA'!$1:$1,0))/INDEX('Data_NSA'!$A:$OK,MATCH($E18,'Data_NSA'!$A:$A,0),MATCH($C18,'Data_NSA'!$1:$1,0))))/(100*(INDEX('Data_NSA'!$A:$OK,MATCH(G$1,'Data_NSA'!$A:$A,0),MATCH("CUUR0000SA0",'Data_NSA'!$1:$1,0))/INDEX('Data_NSA'!$A:$OK,MATCH($E18,'Data_NSA'!$A:$A,0),MATCH("CUUR0000SA0",'Data_NSA'!$1:$1,0)))),"") | H18: =IFERROR(100*($D18*(INDEX('Data_NSA'!$A:$OK,MATCH(H$1,'Data_NSA'!$A:$A,0),MATCH($C18,'Data_NSA'!$1:$1,0))/INDEX('Data_NSA'!$A:$OK,MATCH($E18,'Data_NSA'!$A:$A,0),MATCH($C18,'Data_NSA'!$1:$1,0))))/(100*(INDEX('Data_NSA'!$A:$OK,MATCH(H$1,'Data_NSA'!$A:$A,0),MATCH("CUUR0000SA0",'Data_NSA'!$1:$1,0))/INDEX('Data_NSA'!$A:$OK,MATCH($E18,'Data_NSA'!$A:$A,0),MATCH("CUUR0000SA0",'Data_NSA'!$1:$1,0)))),"") | I18: =IFERROR(100*($D18*(INDEX('Data_NSA'!$A:$OK,MATCH(I$1,'Data_NSA'!$A:$A,0),MATCH($C18,'Data_NSA'!$1:$1,0))/INDEX('Data_NSA'!$A:$OK,MATCH($E18,'Data_NSA'!$A:$A,0),MATCH($C18,'Data_NSA'!$1:$1,0))))/(100*(INDEX('Data_NSA'!$A:$OK,MATCH(I$1,'Data_NSA'!$A:$A,0),MATCH("CUUR0000SA0",'Data_NSA'!$1:$1,0))/INDEX('Data_NSA'!$A:$OK,MATCH($E18,'Data_NSA'!$A:$A,0),MATCH("CUUR0000SA0",'Data_NSA'!$1:$1,0)))),"")
A19: SS02041 | B19: Fresh cakes and cupcakes | C19: CUUR0000SS02041 | E19: 45992 | F19: 2024 | G19: =IFERROR(100*($D19*(INDEX('Data_NSA'!$A:$OK,MATCH(G$1,'Data_NSA'!$A:$A,0),MATCH($C19,'Data_NSA'!$1:$1,0))/INDEX('Data_NSA'!$A:$OK,MATCH($E19,'Data_NSA'!$A:$A,0),MATCH($C19,'Data_NSA'!$1:$1,0))))/(100*(INDEX('Data_NSA'!$A:$OK,MATCH(G$1,'Data_NSA'!$A:$A,0),MATCH("CUUR0000SA0",'Data_NSA'!$1:$1,0))/INDEX('Data_NSA'!$A:$OK,MATCH($E19,'Data_NSA'!$A:$A,0),MATCH("CUUR0000SA0",'Data_NSA'!$1:$1,0)))),"") | H19: =IFERROR(100*($D19*(INDEX('Data_NSA'!$A:$OK,MATCH(H$1,'Data_NSA'!$A:$A,0),MATCH($C19,'Data_NSA'!$1:$1,0))/INDEX('Data_NSA'!$A:$OK,MATCH($E19,'Data_NSA'!$A:$A,0),MATCH($C19,'Data_NSA'!$1:$1,0))))/(100*(INDEX('Data_NSA'!$A:$OK,MATCH(H$1,'Data_NSA'!$A:$A,0),MATCH("CUUR0000SA0",'Data_NSA'!$1:$1,0))/INDEX('Data_NSA'!$A:$OK,MATCH($E19,'Data_NSA'!$A:$A,0),MATCH("CUUR0000SA0",'Data_NSA'!$1:$1,0)))),"") | I19: =IFERROR(100*($D19*(INDEX('Data_NSA'!$A:$OK,MATCH(I$1,'Data_NSA'!$A:$A,0),MATCH($C19,'Data_NSA'!$1:$1,0))/INDEX('Data_NSA'!$A:$OK,MATCH($E19,'Data_NSA'!$A:$A,0),MATCH($C19,'Data_NSA'!$1:$1,0))))/(100*(INDEX('Data_NSA'!$A:$OK,MATCH(I$1,'Data_NSA'!$A:$A,0),MATCH("CUUR0000SA0",'Data_NSA'!$1:$1,0))/INDEX('Data_NSA'!$A:$OK,MATCH($E19,'Data_NSA'!$A:$A,0),MATCH("CUUR0000SA0",'Data_NSA'!$1:$1,0)))),"")
A20: SS02042 | B20: Cookies | C20: CUUR0000SS02042 | E20: 45992 | F20: 2024 | G20: =IFERROR(100*($D20*(INDEX('Data_NSA'!$A:$OK,MATCH(G$1,'Data_NSA'!$A:$A,0),MATCH($C20,'Data_NSA'!$1:$1,0))/INDEX('Data_NSA'!$A:$OK,MATCH($E20,'Data_NSA'!$A:$A,0),MATCH($C20,'Data_NSA'!$1:$1,0))))/(100*(INDEX('Data_NSA'!$A:$OK,MATCH(G$1,'Data_NSA'!$A:$A,0),MATCH("CUUR0000SA0",'Data_NSA'!$1:$1,0))/INDEX('Data_NSA'!$A:$OK,MATCH($E20,'Data_NSA'!$A:$A,0),MATCH("CUUR0000SA0",'Data_NSA'!$1:$1,0)))),"") | H20: =IFERROR(100*($D20*(INDEX('Data_NSA'!$A:$OK,MATCH(H$1,'Data_NSA'!$A:$A,0),MATCH($C20,'Data_NSA'!$1:$1,0))/INDEX('Data_NSA'!$A:$OK,MATCH($E20,'Data_NSA'!$A:$A,0),MATCH($C20,'Data_NSA'!$1:$1,0))))/(100*(INDEX('Data_NSA'!$A:$OK,MATCH(H$1,'Data_NSA'!$A:$A,0),MATCH("CUUR0000SA0",'Data_NSA'!$1:$1,0))/INDEX('Data_NSA'!$A:$OK,MATCH($E20,'Data_NSA'!$A:$A,0),MATCH("CUUR0000SA0",'Data_NSA'!$1:$1,0)))),"") | I20: =IFERROR(100*($D20*(INDEX('Data_NSA'!$A:$OK,MATCH(I$1,'Data_NSA'!$A:$A,0),MATCH($C20,'Data_NSA'!$1:$1,0))/INDEX('Data_NSA'!$A:$OK,MATCH($E20,'Data_NSA'!$A:$A,0),MATCH($C20,'Data_NSA'!$1:$1,0))))/(100*(INDEX('Data_NSA'!$A:$OK,MATCH(I$1,'Data_NSA'!$A:$A,0),MATCH("CUUR0000SA0",'Data_NSA'!$1:$1,0))/INDEX('Data_NSA'!$A:$OK,MATCH($E20,'Data_NSA'!$A:$A,0),MATCH("CUUR0000SA0",'Data_NSA'!$1:$1,0)))),"")
A21: SEFB04 | B21: Other bakery products | C21: CUUR0000SEFB04 | D21: 0.217 | E21: 45992 | F21: 2024 | G21: =IFERROR(100*($D21*(INDEX('Data_NSA'!$A:$OK,MATCH(G$1,'Data_NSA'!$A:$A,0),MATCH($C21,'Data_NSA'!$1:$1,0))/INDEX('Data_NSA'!$A:$OK,MATCH($E21,'Data_NSA'!$A:$A,0),MATCH($C21,'Data_NSA'!$1:$1,0))))/(100*(INDEX('Data_NSA'!$A:$OK,MATCH(G$1,'Data_NSA'!$A:$A,0),MATCH("CUUR0000SA0",'Data_NSA'!$1:$1,0))/INDEX('Data_NSA'!$A:$OK,MATCH($E21,'Data_NSA'!$A:$A,0),MATCH("CUUR0000SA0",'Data_NSA'!$1:$1,0)))),"") | H21: =IFERROR(100*($D21*(INDEX('Data_NSA'!$A:$OK,MATCH(H$1,'Data_NSA'!$A:$A,0),MATCH($C21,'Data_NSA'!$1:$1,0))/INDEX('Data_NSA'!$A:$OK,MATCH($E21,'Data_NSA'!$A:$A,0),MATCH($C21,'Data_NSA'!$1:$1,0))))/(100*(INDEX('Data_NSA'!$A:$OK,MATCH(H$1,'Data_NSA'!$A:$A,0),MATCH("CUUR0000SA0",'Data_NSA'!$1:$1,0))/INDEX('Data_NSA'!$A:$OK,MATCH($E21,'Data_NSA'!$A:$A,0),MATCH("CUUR0000SA0",'Data_NSA'!$1:$1,0)))),"") | I21: =IFERROR(100*($D21*(INDEX('Data_NSA'!$A:$OK,MATCH(I$1,'Data_NSA'!$A:$A,0),MATCH($C21,'Data_NSA'!$1:$1,0))/INDEX('Data_NSA'!$A:$OK,MATCH($E21,'Data_NSA'!$A:$A,0),MATCH($C21,'Data_NSA'!$1:$1,0))))/(100*(INDEX('Data_NSA'!$A:$OK,MATCH(I$1,'Data_NSA'!$A:$A,0),MATCH("CUUR0000SA0",'Data_NSA'!$1:$1,0))/INDEX('Data_NSA'!$A:$OK,MATCH($E21,'Data_NSA'!$A:$A,0),MATCH("CUUR0000SA0",'Data_NSA'!$1:$1,0)))),"")
A22: SS02063 | B22: Fresh sweetrolls, coffeecakes, doughnuts | C22: CUUR0000SS02063 | E22: 45992 | F22: 2024 | G22: =IFERROR(100*($D22*(INDEX('Data_NSA'!$A:$OK,MATCH(G$1,'Data_NSA'!$A:$A,0),MATCH($C22,'Data_NSA'!$1:$1,0))/INDEX('Data_NSA'!$A:$OK,MATCH($E22,'Data_NSA'!$A:$A,0),MATCH($C22,'Data_NSA'!$1:$1,0))))/(100*(INDEX('Data_NSA'!$A:$OK,MATCH(G$1,'Data_NSA'!$A:$A,0),MATCH("CUUR0000SA0",'Data_NSA'!$1:$1,0))/INDEX('Data_NSA'!$A:$OK,MATCH($E22,'Data_NSA'!$A:$A,0),MATCH("CUUR0000SA0",'Data_NSA'!$1:$1,0)))),"") | H22: =IFERROR(100*($D22*(INDEX('Data_NSA'!$A:$OK,MATCH(H$1,'Data_NSA'!$A:$A,0),MATCH($C22,'Data_NSA'!$1:$1,0))/INDEX('Data_NSA'!$A:$OK,MATCH($E22,'Data_NSA'!$A:$A,0),MATCH($C22,'Data_NSA'!$1:$1,0))))/(100*(INDEX('Data_NSA'!$A:$OK,MATCH(H$1,'Data_NSA'!$A:$A,0),MATCH("CUUR0000SA0",'Data_NSA'!$1:$1,0))/INDEX('Data_NSA'!$A:$OK,MATCH($E22,'Data_NSA'!$A:$A,0),MATCH("CUUR0000SA0",'Data_NSA'!$1:$1,0)))),"") | I22: =IFERROR(100*($D22*(INDEX('Data_NSA'!$A:$OK,MATCH(I$1,'Data_NSA'!$A:$A,0),MATCH($C22,'Data_NSA'!$1:$1,0))/INDEX('Data_NSA'!$A:$OK,MATCH($E22,'Data_NSA'!$A:$A,0),MATCH($C22,'Data_NSA'!$1:$1,0))))/(100*(INDEX('Data_NSA'!$A:$OK,MATCH(I$1,'Data_NSA'!$A:$A,0),MATCH("CUUR0000SA0",'Data_NSA'!$1:$1,0))/INDEX('Data_NSA'!$A:$OK,MATCH($E22,'Data_NSA'!$A:$A,0),MATCH("CUUR0000SA0",'Data_NSA'!$1:$1,0)))),"")
A23: SS0206A | B23: Crackers, bread, and cracker products | C23: CUUR0000SS0206A | E23: 45992 | F23: 2024 | G23: =IFERROR(100*($D23*(INDEX('Data_NSA'!$A:$OK,MATCH(G$1,'Data_NSA'!$A:$A,0),MATCH($C23,'Data_NSA'!$1:$1,0))/INDEX('Data_NSA'!$A:$OK,MATCH($E23,'Data_NSA'!$A:$A,0),MATCH($C23,'Data_NSA'!$1:$1,0))))/(100*(INDEX('Data_NSA'!$A:$OK,MATCH(G$1,'Data_NSA'!$A:$A,0),MATCH("CUUR0000SA0",'Data_NSA'!$1:$1,0))/INDEX('Data_NSA'!$A:$OK,MATCH($E23,'Data_NSA'!$A:$A,0),MATCH("CUUR0000SA0",'Data_NSA'!$1:$1,0)))),"") | H23: =IFERROR(100*($D23*(INDEX('Data_NSA'!$A:$OK,MATCH(H$1,'Data_NSA'!$A:$A,0),MATCH($C23,'Data_NSA'!$1:$1,0))/INDEX('Data_NSA'!$A:$OK,MATCH($E23,'Data_NSA'!$A:$A,0),MATCH($C23,'Data_NSA'!$1:$1,0))))/(100*(INDEX('Data_NSA'!$A:$OK,MATCH(H$1,'Data_NSA'!$A:$A,0),MATCH("CUUR0000SA0",'Data_NSA'!$1:$1,0))/INDEX('Data_NSA'!$A:$OK,MATCH($E23,'Data_NSA'!$A:$A,0),MATCH("CUUR0000SA0",'Data_NSA'!$1:$1,0)))),"") | I23: =IFERROR(100*($D23*(INDEX('Data_NSA'!$A:$OK,MATCH(I$1,'Data_NSA'!$A:$A,0),MATCH($C23,'Data_NSA'!$1:$1,0))/INDEX('Data_NSA'!$A:$OK,MATCH($E23,'Data_NSA'!$A:$A,0),MATCH($C23,'Data_NSA'!$1:$1,0))))/(100*(INDEX('Data_NSA'!$A:$OK,MATCH(I$1,'Data_NSA'!$A:$A,0),MATCH("CUUR0000SA0",'Data_NSA'!$1:$1,0))/INDEX('Data_NSA'!$A:$OK,MATCH($E23,'Data_NSA'!$A:$A,0),MATCH("CUUR0000SA0",'Data_NSA'!$1:$1,0)))),"")
A24: SS0206B | B24: Frozen and refrigerated bakery products, pies, tarts, turnovers | C24: CUUR0000SS0206B | E24: 45992 | F24: 2024 | G24: =IFERROR(100*($D24*(INDEX('Data_NSA'!$A:$OK,MATCH(G$1,'Data_NSA'!$A:$A,0),MATCH($C24,'Data_NSA'!$1:$1,0))/INDEX('Data_NSA'!$A:$OK,MATCH($E24,'Data_NSA'!$A:$A,0),MATCH($C24,'Data_NSA'!$1:$1,0))))/(100*(INDEX('Data_NSA'!$A:$OK,MATCH(G$1,'Data_NSA'!$A:$A,0),MATCH("CUUR0000SA0",'Data_NSA'!$1:$1,0))/INDEX('Data_NSA'!$A:$OK,MATCH($E24,'Data_NSA'!$A:$A,0),MATCH("CUUR0000SA0",'Data_NSA'!$1:$1,0)))),"") | H24: =IFERROR(100*($D24*(INDEX('Data_NSA'!$A:$OK,MATCH(H$1,'Data_NSA'!$A:$A,0),MATCH($C24,'Data_NSA'!$1:$1,0))/INDEX('Data_NSA'!$A:$OK,MATCH($E24,'Data_NSA'!$A:$A,0),MATCH($C24,'Data_NSA'!$1:$1,0))))/(100*(INDEX('Data_NSA'!$A:$OK,MATCH(H$1,'Data_NSA'!$A:$A,0),MATCH("CUUR0000SA0",'Data_NSA'!$1:$1,0))/INDEX('Data_NSA'!$A:$OK,MATCH($E24,'Data_NSA'!$A:$A,0),MATCH("CUUR0000SA0",'Data_NSA'!$1:$1,0)))),"") | I24: =IFERROR(100*($D24*(INDEX('Data_NSA'!$A:$OK,MATCH(I$1,'Data_NSA'!$A:$A,0),MATCH($C24,'Data_NSA'!$1:$1,0))/INDEX('Data_NSA'!$A:$OK,MATCH($E24,'Data_NSA'!$A:$A,0),MATCH($C24,'Data_NSA'!$1:$1,0))))/(100*(INDEX('Data_NSA'!$A:$OK,MATCH(I$1,'Data_NSA'!$A:$A,0),MATCH("CUUR0000SA0",'Data_NSA'!$1:$1,0))/INDEX('Data_NSA'!$A:$OK,MATCH($E24,'Data_NSA'!$A:$A,0),MATCH("CUUR0000SA0",'Data_NSA'!$1:$1,0)))),"")
A25: SAF112 | B25: Meats, poultry, fish, and eggs | C25: CUUR0000SAF112 | D25: 1.995 | E25: 45992 | F25: 2024 | G25: =IFERROR(100*($D25*(INDEX('Data_NSA'!$A:$OK,MATCH(G$1,'Data_NSA'!$A:$A,0),MATCH($C25,'Data_NSA'!$1:$1,0))/INDEX('Data_NSA'!$A:$OK,MATCH($E25,'Data_NSA'!$A:$A,0),MATCH($C25,'Data_NSA'!$1:$1,0))))/(100*(INDEX('Data_NSA'!$A:$OK,MATCH(G$1,'Data_NSA'!$A:$A,0),MATCH("CUUR0000SA0",'Data_NSA'!$1:$1,0))/INDEX('Data_NSA'!$A:$OK,MATCH($E25,'Data_NSA'!$A:$A,0),MATCH("CUUR0000SA0",'Data_NSA'!$1:$1,0)))),"") | H25: =IFERROR(100*($D25*(INDEX('Data_NSA'!$A:$OK,MATCH(H$1,'Data_NSA'!$A:$A,0),MATCH($C25,'Data_NSA'!$1:$1,0))/INDEX('Data_NSA'!$A:$OK,MATCH($E25,'Data_NSA'!$A:$A,0),MATCH($C25,'Data_NSA'!$1:$1,0))))/(100*(INDEX('Data_NSA'!$A:$OK,MATCH(H$1,'Data_NSA'!$A:$A,0),MATCH("CUUR0000SA0",'Data_NSA'!$1:$1,0))/INDEX('Data_NSA'!$A:$OK,MATCH($E25,'Data_NSA'!$A:$A,0),MATCH("CUUR0000SA0",'Data_NSA'!$1:$1,0)))),"") | I25: =IFERROR(100*($D25*(INDEX('Data_NSA'!$A:$OK,MATCH(I$1,'Data_NSA'!$A:$A,0),MATCH($C25,'Data_NSA'!$1:$1,0))/INDEX('Data_NSA'!$A:$OK,MATCH($E25,'Data_NSA'!$A:$A,0),MATCH($C25,'Data_NSA'!$1:$1,0))))/(100*(INDEX('Data_NSA'!$A:$OK,MATCH(I$1,'Data_NSA'!$A:$A,0),MATCH("CUUR0000SA0",'Data_NSA'!$1:$1,0))/INDEX('Data_NSA'!$A:$OK,MATCH($E25,'Data_NSA'!$A:$A,0),MATCH("CUUR0000SA0",'Data_NSA'!$1:$1,0)))),"")
A26: SAF1121 | B26: Meats, poultry, and fish | C26: CUUR0000SAF1121 | D26: 1.862 | E26: 45992 | F26: 2024 | G26: =IFERROR(100*($D26*(INDEX('Data_NSA'!$A:$OK,MATCH(G$1,'Data_NSA'!$A:$A,0),MATCH($C26,'Data_NSA'!$1:$1,0))/INDEX('Data_NSA'!$A:$OK,MATCH($E26,'Data_NSA'!$A:$A,0),MATCH($C26,'Data_NSA'!$1:$1,0))))/(100*(INDEX('Data_NSA'!$A:$OK,MATCH(G$1,'Data_NSA'!$A:$A,0),MATCH("CUUR0000SA0",'Data_NSA'!$1:$1,0))/INDEX('Data_NSA'!$A:$OK,MATCH($E26,'Data_NSA'!$A:$A,0),MATCH("CUUR0000SA0",'Data_NSA'!$1:$1,0)))),"") | H26: =IFERROR(100*($D26*(INDEX('Data_NSA'!$A:$OK,MATCH(H$1,'Data_NSA'!$A:$A,0),MATCH($C26,'Data_NSA'!$1:$1,0))/INDEX('Data_NSA'!$A:$OK,MATCH($E26,'Data_NSA'!$A:$A,0),MATCH($C26,'Data_NSA'!$1:$1,0))))/(100*(INDEX('Data_NSA'!$A:$OK,MATCH(H$1,'Data_NSA'!$A:$A,0),MATCH("CUUR0000SA0",'Data_NSA'!$1:$1,0))/INDEX('Data_NSA'!$A:$OK,MATCH($E26,'Data_NSA'!$A:$A,0),MATCH("CUUR0000SA0",'Data_NSA'!$1:$1,0)))),"") | I26: =IFERROR(100*($D26*(INDEX('Data_NSA'!$A:$OK,MATCH(I$1,'Data_NSA'!$A:$A,0),MATCH($C26,'Data_NSA'!$1:$1,0))/INDEX('Data_NSA'!$A:$OK,MATCH($E26,'Data_NSA'!$A:$A,0),MATCH($C26,'Data_NSA'!$1:$1,0))))/(100*(INDEX('Data_NSA'!$A:$OK,MATCH(I$1,'Data_NSA'!$A:$A,0),MATCH("CUUR0000SA0",'Data_NSA'!$1:$1,0))/INDEX('Data_NSA'!$A:$OK,MATCH($E26,'Data_NSA'!$A:$A,0),MATCH("CUUR0000SA0",'Data_NSA'!$1:$1,0)))),"")
A27: SAF11211 | B27: Meats | C27: CUUR0000SAF11211 | D27: 1.186 | E27: 45992 | F27: 2024 | G27: =IFERROR(100*($D27*(INDEX('Data_NSA'!$A:$OK,MATCH(G$1,'Data_NSA'!$A:$A,0),MATCH($C27,'Data_NSA'!$1:$1,0))/INDEX('Data_NSA'!$A:$OK,MATCH($E27,'Data_NSA'!$A:$A,0),MATCH($C27,'Data_NSA'!$1:$1,0))))/(100*(INDEX('Data_NSA'!$A:$OK,MATCH(G$1,'Data_NSA'!$A:$A,0),MATCH("CUUR0000SA0",'Data_NSA'!$1:$1,0))/INDEX('Data_NSA'!$A:$OK,MATCH($E27,'Data_NSA'!$A:$A,0),MATCH("CUUR0000SA0",'Data_NSA'!$1:$1,0)))),"") | H27: =IFERROR(100*($D27*(INDEX('Data_NSA'!$A:$OK,MATCH(H$1,'Data_NSA'!$A:$A,0),MATCH($C27,'Data_NSA'!$1:$1,0))/INDEX('Data_NSA'!$A:$OK,MATCH($E27,'Data_NSA'!$A:$A,0),MATCH($C27,'Data_NSA'!$1:$1,0))))/(100*(INDEX('Data_NSA'!$A:$OK,MATCH(H$1,'Data_NSA'!$A:$A,0),MATCH("CUUR0000SA0",'Data_NSA'!$1:$1,0))/INDEX('Data_NSA'!$A:$OK,MATCH($E27,'Data_NSA'!$A:$A,0),MATCH("CUUR0000SA0",'Data_NSA'!$1:$1,0)))),"") | I27: =IFERROR(100*($D27*(INDEX('Data_NSA'!$A:$OK,MATCH(I$1,'Data_NSA'!$A:$A,0),MATCH($C27,'Data_NSA'!$1:$1,0))/INDEX('Data_NSA'!$A:$OK,MATCH($E27,'Data_NSA'!$A:$A,0),MATCH($C27,'Data_NSA'!$1:$1,0))))/(100*(INDEX('Data_NSA'!$A:$OK,MATCH(I$1,'Data_NSA'!$A:$A,0),MATCH("CUUR0000SA0",'Data_NSA'!$1:$1,0))/INDEX('Data_NSA'!$A:$OK,MATCH($E27,'Data_NSA'!$A:$A,0),MATCH("CUUR0000SA0",'Data_NSA'!$1:$1,0)))),"")
A28: SEFC | B28: Beef and veal | C28: CUUR0000SEFC | D28: 0.638 | E28: 45992 | F28: 2024 | G28: =IFERROR(100*($D28*(INDEX('Data_NSA'!$A:$OK,MATCH(G$1,'Data_NSA'!$A:$A,0),MATCH($C28,'Data_NSA'!$1:$1,0))/INDEX('Data_NSA'!$A:$OK,MATCH($E28,'Data_NSA'!$A:$A,0),MATCH($C28,'Data_NSA'!$1:$1,0))))/(100*(INDEX('Data_NSA'!$A:$OK,MATCH(G$1,'Data_NSA'!$A:$A,0),MATCH("CUUR0000SA0",'Data_NSA'!$1:$1,0))/INDEX('Data_NSA'!$A:$OK,MATCH($E28,'Data_NSA'!$A:$A,0),MATCH("CUUR0000SA0",'Data_NSA'!$1:$1,0)))),"") | H28: =IFERROR(100*($D28*(INDEX('Data_NSA'!$A:$OK,MATCH(H$1,'Data_NSA'!$A:$A,0),MATCH($C28,'Data_NSA'!$1:$1,0))/INDEX('Data_NSA'!$A:$OK,MATCH($E28,'Data_NSA'!$A:$A,0),MATCH($C28,'Data_NSA'!$1:$1,0))))/(100*(INDEX('Data_NSA'!$A:$OK,MATCH(H$1,'Data_NSA'!$A:$A,0),MATCH("CUUR0000SA0",'Data_NSA'!$1:$1,0))/INDEX('Data_NSA'!$A:$OK,MATCH($E28,'Data_NSA'!$A:$A,0),MATCH("CUUR0000SA0",'Data_NSA'!$1:$1,0)))),"") | I28: =IFERROR(100*($D28*(INDEX('Data_NSA'!$A:$OK,MATCH(I$1,'Data_NSA'!$A:$A,0),MATCH($C28,'Data_NSA'!$1:$1,0))/INDEX('Data_NSA'!$A:$OK,MATCH($E28,'Data_NSA'!$A:$A,0),MATCH($C28,'Data_NSA'!$1:$1,0))))/(100*(INDEX('Data_NSA'!$A:$OK,MATCH(I$1,'Data_NSA'!$A:$A,0),MATCH("CUUR0000SA0",'Data_NSA'!$1:$1,0))/INDEX('Data_NSA'!$A:$OK,MATCH($E28,'Data_NSA'!$A:$A,0),MATCH("CUUR0000SA0",'Data_NSA'!$1:$1,0)))),"")
A29: SEFC01 | B29: Uncooked ground beef | C29: CUUR0000SEFC01 | D29: 0.236 | E29: 45992 | F29: 2024 | G29: =IFERROR(100*($D29*(INDEX('Data_NSA'!$A:$OK,MATCH(G$1,'Data_NSA'!$A:$A,0),MATCH($C29,'Data_NSA'!$1:$1,0))/INDEX('Data_NSA'!$A:$OK,MATCH($E29,'Data_NSA'!$A:$A,0),MATCH($C29,'Data_NSA'!$1:$1,0))))/(100*(INDEX('Data_NSA'!$A:$OK,MATCH(G$1,'Data_NSA'!$A:$A,0),MATCH("CUUR0000SA0",'Data_NSA'!$1:$1,0))/INDEX('Data_NSA'!$A:$OK,MATCH($E29,'Data_NSA'!$A:$A,0),MATCH("CUUR0000SA0",'Data_NSA'!$1:$1,0)))),"") | H29: =IFERROR(100*($D29*(INDEX('Data_NSA'!$A:$OK,MATCH(H$1,'Data_NSA'!$A:$A,0),MATCH($C29,'Data_NSA'!$1:$1,0))/INDEX('Data_NSA'!$A:$OK,MATCH($E29,'Data_NSA'!$A:$A,0),MATCH($C29,'Data_NSA'!$1:$1,0))))/(100*(INDEX('Data_NSA'!$A:$OK,MATCH(H$1,'Data_NSA'!$A:$A,0),MATCH("CUUR0000SA0",'Data_NSA'!$1:$1,0))/INDEX('Data_NSA'!$A:$OK,MATCH($E29,'Data_NSA'!$A:$A,0),MATCH("CUUR0000SA0",'Data_NSA'!$1:$1,0)))),"") | I29: =IFERROR(100*($D29*(INDEX('Data_NSA'!$A:$OK,MATCH(I$1,'Data_NSA'!$A:$A,0),MATCH($C29,'Data_NSA'!$1:$1,0))/INDEX('Data_NSA'!$A:$OK,MATCH($E29,'Data_NSA'!$A:$A,0),MATCH($C29,'Data_NSA'!$1:$1,0))))/(100*(INDEX('Data_NSA'!$A:$OK,MATCH(I$1,'Data_NSA'!$A:$A,0),MATCH("CUUR0000SA0",'Data_NSA'!$1:$1,0))/INDEX('Data_NSA'!$A:$OK,MATCH($E29,'Data_NSA'!$A:$A,0),MATCH("CUUR0000SA0",'Data_NSA'!$1:$1,0)))),"")
A30: SEFC02 | B30: Uncooked beef roasts | C30: CUUR0000SEFC02 | D30: 0.087 | E30: 45992 | F30: 2024 | G30: =IFERROR(100*($D30*(INDEX('Data_NSA'!$A:$OK,MATCH(G$1,'Data_NSA'!$A:$A,0),MATCH($C30,'Data_NSA'!$1:$1,0))/INDEX('Data_NSA'!$A:$OK,MATCH($E30,'Data_NSA'!$A:$A,0),MATCH($C30,'Data_NSA'!$1:$1,0))))/(100*(INDEX('Data_NSA'!$A:$OK,MATCH(G$1,'Data_NSA'!$A:$A,0),MATCH("CUUR0000SA0",'Data_NSA'!$1:$1,0))/INDEX('Data_NSA'!$A:$OK,MATCH($E30,'Data_NSA'!$A:$A,0),MATCH("CUUR0000SA0",'Data_NSA'!$1:$1,0)))),"") | H30: =IFERROR(100*($D30*(INDEX('Data_NSA'!$A:$OK,MATCH(H$1,'Data_NSA'!$A:$A,0),MATCH($C30,'Data_NSA'!$1:$1,0))/INDEX('Data_NSA'!$A:$OK,MATCH($E30,'Data_NSA'!$A:$A,0),MATCH($C30,'Data_NSA'!$1:$1,0))))/(100*(INDEX('Data_NSA'!$A:$OK,MATCH(H$1,'Data_NSA'!$A:$A,0),MATCH("CUUR0000SA0",'Data_NSA'!$1:$1,0))/INDEX('Data_NSA'!$A:$OK,MATCH($E30,'Data_NSA'!$A:$A,0),MATCH("CUUR0000SA0",'Data_NSA'!$1:$1,0)))),"") | I30: =IFERROR(100*($D30*(INDEX('Data_NSA'!$A:$OK,MATCH(I$1,'Data_NSA'!$A:$A,0),MATCH($C30,'Data_NSA'!$1:$1,0))/INDEX('Data_NSA'!$A:$OK,MATCH($E30,'Data_NSA'!$A:$A,0),MATCH($C30,'Data_NSA'!$1:$1,0))))/(100*(INDEX('Data_NSA'!$A:$OK,MATCH(I$1,'Data_NSA'!$A:$A,0),MATCH("CUUR0000SA0",'Data_NSA'!$1:$1,0))/INDEX('Data_NSA'!$A:$OK,MATCH($E30,'Data_NSA'!$A:$A,0),MATCH("CUUR0000SA0",'Data_NSA'!$1:$1,0)))),"")
A31: SEFC03 | B31: Uncooked beef steaks | C31: CUUR0000SEFC03 | D31: 0.24 | E31: 45992 | F31: 2024 | G31: =IFERROR(100*($D31*(INDEX('Data_NSA'!$A:$OK,MATCH(G$1,'Data_NSA'!$A:$A,0),MATCH($C31,'Data_NSA'!$1:$1,0))/INDEX('Data_NSA'!$A:$OK,MATCH($E31,'Data_NSA'!$A:$A,0),MATCH($C31,'Data_NSA'!$1:$1,0))))/(100*(INDEX('Data_NSA'!$A:$OK,MATCH(G$1,'Data_NSA'!$A:$A,0),MATCH("CUUR0000SA0",'Data_NSA'!$1:$1,0))/INDEX('Data_NSA'!$A:$OK,MATCH($E31,'Data_NSA'!$A:$A,0),MATCH("CUUR0000SA0",'Data_NSA'!$1:$1,0)))),"") | H31: =IFERROR(100*($D31*(INDEX('Data_NSA'!$A:$OK,MATCH(H$1,'Data_NSA'!$A:$A,0),MATCH($C31,'Data_NSA'!$1:$1,0))/INDEX('Data_NSA'!$A:$OK,MATCH($E31,'Data_NSA'!$A:$A,0),MATCH($C31,'Data_NSA'!$1:$1,0))))/(100*(INDEX('Data_NSA'!$A:$OK,MATCH(H$1,'Data_NSA'!$A:$A,0),MATCH("CUUR0000SA0",'Data_NSA'!$1:$1,0))/INDEX('Data_NSA'!$A:$OK,MATCH($E31,'Data_NSA'!$A:$A,0),MATCH("CUUR0000SA0",'Data_NSA'!$1:$1,0)))),"") | I31: =IFERROR(100*($D31*(INDEX('Data_NSA'!$A:$OK,MATCH(I$1,'Data_NSA'!$A:$A,0),MATCH($C31,'Data_NSA'!$1:$1,0))/INDEX('Data_NSA'!$A:$OK,MATCH($E31,'Data_NSA'!$A:$A,0),MATCH($C31,'Data_NSA'!$1:$1,0))))/(100*(INDEX('Data_NSA'!$A:$OK,MATCH(I$1,'Data_NSA'!$A:$A,0),MATCH("CUUR0000SA0",'Data_NSA'!$1:$1,0))/INDEX('Data_NSA'!$A:$OK,MATCH($E31,'Data_NSA'!$A:$A,0),MATCH("CUUR0000SA0",'Data_NSA'!$1:$1,0)))),"")
A32: SEFC04 | B32: Uncooked other beef and veal | C32: CUUR0000SEFC04 | D32: 0.076 | E32: 45992 | F32: 2024 | G32: =IFERROR(100*($D32*(INDEX('Data_NSA'!$A:$OK,MATCH(G$1,'Data_NSA'!$A:$A,0),MATCH($C32,'Data_NSA'!$1:$1,0))/INDEX('Data_NSA'!$A:$OK,MATCH($E32,'Data_NSA'!$A:$A,0),MATCH($C32,'Data_NSA'!$1:$1,0))))/(100*(INDEX('Data_NSA'!$A:$OK,MATCH(G$1,'Data_NSA'!$A:$A,0),MATCH("CUUR0000SA0",'Data_NSA'!$1:$1,0))/INDEX('Data_NSA'!$A:$OK,MATCH($E32,'Data_NSA'!$A:$A,0),MATCH("CUUR0000SA0",'Data_NSA'!$1:$1,0)))),"") | H32: =IFERROR(100*($D32*(INDEX('Data_NSA'!$A:$OK,MATCH(H$1,'Data_NSA'!$A:$A,0),MATCH($C32,'Data_NSA'!$1:$1,0))/INDEX('Data_NSA'!$A:$OK,MATCH($E32,'Data_NSA'!$A:$A,0),MATCH($C32,'Data_NSA'!$1:$1,0))))/(100*(INDEX('Data_NSA'!$A:$OK,MATCH(H$1,'Data_NSA'!$A:$A,0),MATCH("CUUR0000SA0",'Data_NSA'!$1:$1,0))/INDEX('Data_NSA'!$A:$OK,MATCH($E32,'Data_NSA'!$A:$A,0),MATCH("CUUR0000SA0",'Data_NSA'!$1:$1,0)))),"") | I32: =IFERROR(100*($D32*(INDEX('Data_NSA'!$A:$OK,MATCH(I$1,'Data_NSA'!$A:$A,0),MATCH($C32,'Data_NSA'!$1:$1,0))/INDEX('Data_NSA'!$A:$OK,MATCH($E32,'Data_NSA'!$A:$A,0),MATCH($C32,'Data_NSA'!$1:$1,0))))/(100*(INDEX('Data_NSA'!$A:$OK,MATCH(I$1,'Data_NSA'!$A:$A,0),MATCH("CUUR0000SA0",'Data_NSA'!$1:$1,0))/INDEX('Data_NSA'!$A:$OK,MATCH($E32,'Data_NSA'!$A:$A,0),MATCH("CUUR0000SA0",'Data_NSA'!$1:$1,0)))),"")
A33: SEFD | B33: Pork | C33: CUUR0000SEFD | D33: 0.34 | E33: 45992 | F33: 2024 | G33: =IFERROR(100*($D33*(INDEX('Data_NSA'!$A:$OK,MATCH(G$1,'Data_NSA'!$A:$A,0),MATCH($C33,'Data_NSA'!$1:$1,0))/INDEX('Data_NSA'!$A:$OK,MATCH($E33,'Data_NSA'!$A:$A,0),MATCH($C33,'Data_NSA'!$1:$1,0))))/(100*(INDEX('Data_NSA'!$A:$OK,MATCH(G$1,'Data_NSA'!$A:$A,0),MATCH("CUUR0000SA0",'Data_NSA'!$1:$1,0))/INDEX('Data_NSA'!$A:$OK,MATCH($E33,'Data_NSA'!$A:$A,0),MATCH("CUUR0000SA0",'Data_NSA'!$1:$1,0)))),"") | H33: =IFERROR(100*($D33*(INDEX('Data_NSA'!$A:$OK,MATCH(H$1,'Data_NSA'!$A:$A,0),MATCH($C33,'Data_NSA'!$1:$1,0))/INDEX('Data_NSA'!$A:$OK,MATCH($E33,'Data_NSA'!$A:$A,0),MATCH($C33,'Data_NSA'!$1:$1,0))))/(100*(INDEX('Data_NSA'!$A:$OK,MATCH(H$1,'Data_NSA'!$A:$A,0),MATCH("CUUR0000SA0",'Data_NSA'!$1:$1,0))/INDEX('Data_NSA'!$A:$OK,MATCH($E33,'Data_NSA'!$A:$A,0),MATCH("CUUR0000SA0",'Data_NSA'!$1:$1,0)))),"") | I33: =IFERROR(100*($D33*(INDEX('Data_NSA'!$A:$OK,MATCH(I$1,'Data_NSA'!$A:$A,0),MATCH($C33,'Data_NSA'!$1:$1,0))/INDEX('Data_NSA'!$A:$OK,MATCH($E33,'Data_NSA'!$A:$A,0),MATCH($C33,'Data_NSA'!$1:$1,0))))/(100*(INDEX('Data_NSA'!$A:$OK,MATCH(I$1,'Data_NSA'!$A:$A,0),MATCH("CUUR0000SA0",'Data_NSA'!$1:$1,0))/INDEX('Data_NSA'!$A:$OK,MATCH($E33,'Data_NSA'!$A:$A,0),MATCH("CUUR0000SA0",'Data_NSA'!$1:$1,0)))),"")
A34: SEFD01 | B34: Bacon, breakfast sausage, and related products | C34: CUUR0000SEFD01 | D34: 0.131 | E34: 45992 | F34: 2024 | G34: =IFERROR(100*($D34*(INDEX('Data_NSA'!$A:$OK,MATCH(G$1,'Data_NSA'!$A:$A,0),MATCH($C34,'Data_NSA'!$1:$1,0))/INDEX('Data_NSA'!$A:$OK,MATCH($E34,'Data_NSA'!$A:$A,0),MATCH($C34,'Data_NSA'!$1:$1,0))))/(100*(INDEX('Data_NSA'!$A:$OK,MATCH(G$1,'Data_NSA'!$A:$A,0),MATCH("CUUR0000SA0",'Data_NSA'!$1:$1,0))/INDEX('Data_NSA'!$A:$OK,MATCH($E34,'Data_NSA'!$A:$A,0),MATCH("CUUR0000SA0",'Data_NSA'!$1:$1,0)))),"") | H34: =IFERROR(100*($D34*(INDEX('Data_NSA'!$A:$OK,MATCH(H$1,'Data_NSA'!$A:$A,0),MATCH($C34,'Data_NSA'!$1:$1,0))/INDEX('Data_NSA'!$A:$OK,MATCH($E34,'Data_NSA'!$A:$A,0),MATCH($C34,'Data_NSA'!$1:$1,0))))/(100*(INDEX('Data_NSA'!$A:$OK,MATCH(H$1,'Data_NSA'!$A:$A,0),MATCH("CUUR0000SA0",'Data_NSA'!$1:$1,0))/INDEX('Data_NSA'!$A:$OK,MATCH($E34,'Data_NSA'!$A:$A,0),MATCH("CUUR0000SA0",'Data_NSA'!$1:$1,0)))),"") | I34: =IFERROR(100*($D34*(INDEX('Data_NSA'!$A:$OK,MATCH(I$1,'Data_NSA'!$A:$A,0),MATCH($C34,'Data_NSA'!$1:$1,0))/INDEX('Data_NSA'!$A:$OK,MATCH($E34,'Data_NSA'!$A:$A,0),MATCH($C34,'Data_NSA'!$1:$1,0))))/(100*(INDEX('Data_NSA'!$A:$OK,MATCH(I$1,'Data_NSA'!$A:$A,0),MATCH("CUUR0000SA0",'Data_NSA'!$1:$1,0))/INDEX('Data_NSA'!$A:$OK,MATCH($E34,'Data_NSA'!$A:$A,0),MATCH("CUUR0000SA0",'Data_NSA'!$1:$1,0)))),"")
